Workbook

Sheet 2024
A1: 生活 | B1: =SUMIF(D:D,A1,S:S) -> 1001606.3 | C1: =B1/$B$4 -> 0.45084877 | J1: 月支出估計 | L1: 年支出估計
A2: 想要&奢侈品 | B2: =SUMIF(D:D,A2,S:S) -> 126625 | C2: =B2/$B$4 -> 0.056997169 | J2: 185000 | L2: =J2*12+K2 -> 2220000 | M2: =2200000-B4 -> -21601.563
A3: 一次性支出 | B3: =SUMIF(D:D,A3,S:S) -> 1093370.2 | C3: =B3/$B$4 -> 0.49215406 | AD3: 202312
A4: Total | B4: =SUMIF(D:D,A4,S:S) -> 2221601.6 | C4: =B4-B89 -> 1527424.6 | AD4: 202412 | AE4: =AE5/$AD$5 -> 0.14831687 | AF4: =AF5/$AD$5 -> 0.009294646 | AG4: =AG5/$AD$5 -> 0.03573278 | AH4: =AH5/$AD$5 -> 0.035431646 | AI4: =AI5/$AD$5 -> 0.15607704 | AJ4: =AJ5/$AD$5 -> 0.058532098 | AK4: =AK5/$AD$5 -> 0.0074636846 | AL4: =AL5/$AD$5 -> 0.033067136 | ... AU4: =AU5/$AD$5 -> 0.02094435
A5: Total-旅遊 | B5: =B4-AQ5 -> 1335182.3 | AD5: =SUM(AE5:AU5) -> 2221601.6 | AE5: =SUM(AE10:AE21) -> 329501 | AF5: =SUM(AF10:AF21) -> 20649 | AG5: =SUM(AG10:AG21) -> 79384 | AH5: =SUM(AH10:AH21) -> 78715 | AI5: =SUM(AI10:AI21) -> 346741 | AJ5: =SUM(AJ10:AJ21) -> 130035 | AK5: =SUM(AK10:AK21) -> 16581.333 | AL5: =SUM(AL10:AL21) -> 73462 | ... AU5: =SUM(AU10:AU21) -> 46530
A6: 占預計支出比例 | B6: =B4/L2 -> 1.0007214 | F6: =F7/$S$7 -> 0.3392494 | G6: =G7/$S$7 -> 0.0030473511 | H6: =H7/$S$7 -> 0.24832073 | I6: =I7/$S$7 -> 0.019109637 | J6: =J7/$S$7 -> 0.0062427936 | K6: =K7/$S$7 -> 0.0050823695 | L6: =L7/$S$7 -> 0.056734296 | M6: =M7/$S$7 -> 0.12439764 | ... R6: =R7/$S$7 -> 0.0019175356 | AE6: =W9 -> 生活 | AL6: =X9 -> 想要&奢侈品 | AQ6: =Y9 -> 一次性支出
F7: =SUMIF($D$9:$D$1012,"Total",F9:F1012) -> 753677 | G7: =SUMIF($D$9:$D$1012,"Total",G9:G1012) -> 6770 | H7: =SUMIF($D$9:$D$1012,"Total",H9:H1012) -> 551669.73 | I7: =SUMIF($D$9:$D$1012,"Total",I9:I1012) -> 42454 | J7: =SUMIF($D$9:$D$1012,"Total",J9:J1012) -> 13869 | K7: =SUMIF($D$9:$D$1012,"Total",K9:K1012) -> 11291 | L7: =SUMIF($D$9:$D$1012,"Total",L9:L1012) -> 126041 | M7: =SUMIF($D$9:$D$1012,"Total",M9:M1012) -> 276362 | ... R7: =SUMIF($D$9:$D$1012,"Total",R9:R1012) -> 4260 | S7: =SUM(F7:R7) -> 2221601.6 | W7: =W8/$AD$5 -> 0.45084877 | X7: =X8/$AD$5 -> 0.056997169 | Y7: =Y8/$AD$5 -> 0.49215406 | Z7: =Z8/$AD$5 -> 1 | AD7: 占比%/YOY% | AE7: =ROUND(W7*100,2)&"%"&" / "&ROUND((SUMPRODUCT((VALUE($AD$10:$AD$21)<=VALUE($AD$4))*(AE10:AK21))/SUMPRODUCT((VALUE('2023'!$AD$10:$AD$21)<=VALUE($AD$3))*('2023'!AE$10:AK$21))-1)*100,2)&"%" -> 45.08% / -4.26% | AL7: =ROUND(X7*100,2)&"%"&" / "&ROUND((SUMPRODUCT((VALUE($AD$10:$AD$21)<=VALUE($AD$4))*(AL10:AP21))/SUMPRODUCT((VALUE('2023'!$AD$10:$AD$21)<=VALUE($AD$3))*('2023'!AL$10:AP$21))-1)*100,2)&"%" -> 5.7% / -23.06% | AQ7: =ROUND(Y7*100,2)&"%"&" / "&ROUND((SUMPRODUCT((VALUE($AD$10:$AD$21)<=VALUE($AD$4))*(AQ10:AU21))/SUMPRODUCT((VALUE('2023'!$AD$10:$AD$21)<=VALUE($AD$3))*('2023'!AQ$10:AU$21))-1)*100,2)&"%" -> 49.22% / -0.19%
C8: 年月 | F8: 其他現金支出 | G8: 匯豐 | H8: 台新ALL | I8: 玉山ALL | J8: 樂天 | K8: 上海 | L8: 國泰KOKO&COSTCO | M8: 合庫+永豐+星展 | N8: 聯邦微風卡 | O8: 王董Creditcard | P8: 中信LinePAy | Q8: 孝敬長輩 | R8: 合庫 | S8: Total | W8: =SUM(W10:W21) -> 1001606.3 | X8: =SUM(X10:X21) -> 126625 | Y8: =SUM(Y10:Y21) -> 1093370.2 | Z8: =SUM(Z10:Z21) -> 2221601.6 | AD8: =SUMPRODUCT((VALUE($AD$10:$AD$21)<=VALUE($AD$4))*(AE10:AU21))/SUMPRODUCT((VALUE('2023'!$AD$10:$AD$21)<=VALUE($AD$3))*('2023'!AE$10:AU$21))-1 -> -0.036685346 | AE8: =SUMPRODUCT((VALUE($AD$10:$AD$21)<=VALUE($AD$4))*(AE10:AE21))/SUMPRODUCT((VALUE('2023'!$AD$10:$AD$21)<=VALUE($AD$3))*('2023'!AE$10:AE$21))-1 -> 0.0092068791 | AF8: =(SUMPRODUCT((VALUE($AD$10:$AD$21)<=VALUE($AD$4))*(AF10:AF21))+SUMPRODUCT((VALUE($AD$10:$AD$21)<=VALUE($AD$4))*(AG10:AG21))+SUMPRODUCT((VALUE($AD$10:$AD$21)<=VALUE($AD$4))*(AH10:AH21)))/(SUMPRODUCT((VALUE('2023'!$AD$10:$AD$21)<=VALUE($AD$3))*('2023'!AF$10:AF$21))+SUMPRODUCT((VALUE('2023'!$AD$10:$AD$21)<=VALUE($AD$3))*('2023'!AG$10:AG$21))+SUMPRODUCT((VALUE('2023'!$AD$10:$AD$21)<=VALUE($AD$3))*('2023'!AK$10:AK$21)))-1 -> -0.18778967 | AI8: =(SUMPRODUCT((VALUE($AD$10:$AD$21)<=VALUE($AD$4))*(AI10:AI21))+SUMPRODUCT((VALUE($AD$10:$AD$21)<=VALUE($AD$4))*(AJ10:AJ21)))/(SUMPRODUCT((VALUE('2023'!$AD$10:$AD$21)<=VALUE($AD$3))*('2023'!AI$10:AI$21))+SUMPRODUCT((VALUE('2023'!$AD$10:$AD$21)<=VALUE($AD$3))*('2023'!AJ$10:AJ$21)))-1 -> -0.02661628 | AK8: =SUMPRODUCT((VALUE($AD$10:$AD$21)<=VALUE($AD$4))*(AK10:AK21))/SUMPRODUCT((VALUE('2023'!$AD$10:$AD$21)<=VALUE($AD$3))*('2023'!AH$10:AH$21))-1 -> 0.68680909 | AL8: =SUMPRODUCT((VALUE($AD$10:$AD$21)<=VALUE($AD$4))*(AL10:AL21))/SUMPRODUCT((VALUE('2023'!$AD$10:$AD$21)<=VALUE($AD$3))*('2023'!AL10:AL21))-1 -> 1.1386317 | AM8: =SUMPRODUCT((VALUE($AD$10:$AD$21)<=VALUE($AD$4))*(AM10:AM21))/SUMPRODUCT((VALUE('2023'!$AD$10:$AD$21)<=VALUE($AD$3))*('2023'!AM10:AM21))-1 -> -0.65411333 | AN8: =SUMPRODUCT((VALUE($AD$10:$AD$21)<=VALUE($AD$4))*(AN10:AN21))/SUMPRODUCT((VALUE('2023'!$AD$10:$AD$21)<=VALUE($AD$3))*('2023'!AN10:AN21))-1 -> -0.2604097 | AO8: =SUMPRODUCT((VALUE($AD$10:$AD$21)<=VALUE($AD$4))*(AO10:AO21))/SUMPRODUCT((VALUE('2023'!$AD$10:$AD$21)<=VALUE($AD$3))*('2023'!AO10:AO21))-1 -> -0.020076942 | AP8: =SUMPRODUCT((VALUE($AD$10:$AD$21)<=VALUE($AD$4))*(AP10:AP21))/SUMPRODUCT((VALUE('2023'!$AD$10:$AD$21)<=VALUE($AD$3))*('2023'!AP10:AP21))-1 -> -0.73799783 | AQ8: =SUMPRODUCT((VALUE($AD$10:$AD$21)<=VALUE($AD$4))*(AQ10:AQ21))/SUMPRODUCT((VALUE('2023'!$AD$10:$AD$21)<=VALUE($AD$3))*('2023'!AQ10:AQ21))-1 -> 0.7295934 | AR8: =SUMPRODUCT((VALUE($AD$10:$AD$21)<=VALUE($AD$4))*(AR10:AR21))/SUMPRODUCT((VALUE('2023'!$AD$10:$AD$21)<=VALUE($AD$3))*('2023'!AR10:AR21))-1 -> 0.26962019 | AS8: =SUMPRODUCT((VALUE($AD$10:$AD$21)<=VALUE($AD$4))*(AS10:AS21))/SUMPRODUCT((VALUE('2023'!$AD$10:$AD$21)<=VALUE($AD$3))*('2023'!AS10:AS21))-1 -> -0.78646575 | ... AU8: =SUMPRODUCT((VALUE($AD$10:$AD$21)<=VALUE($AD$4))*(AU10:AU21))/SUMPRODUCT((VALUE('2023'!$AD$10:$AD$21)<=VALUE($AD$3))*('2023'!AU10:AU21))-1 -> -0.633772
A9: 月份 | B9: 202401 | C9: 202401 | D9: 生活 | E9: 食 | F9: =65+60+130+270+80+110+1020+120+65+255+75+300+1224 -> 3774 | H9: =195+258+179+85+95+225+185+195+195+540+341+84+105+180+110+45+150+84+166+470+50 -> 3937 | I9: 420 | M9: =199+258+899 -> 1356 | O9: =195+250+250+265+280 -> 1240 | Q9: =2000+2000+2000+2000 -> 8000 | S9: =SUM(F9:R9) -> 18727 | T9: =SUM(S9:S15) -> 70147 | V9: 月份 | W9: =A1 -> 生活 | X9: 想要&奢侈品 | Y9: =A3 -> 一次性支出 | Z9: Total | AD9: 月份 | AE9: 食 | AF9: 衣 | AG9: 住 | AH9: 行 | AI9: 育-基本 | AJ9: 育-才藝 | AK9: 醫療費用 | AL9: N | AM9: A | AN9: L | AO9: D | AP9: 其它 | AQ9: 旅遊 | AR9: 家庭聚會 | AS9: 稅費 | AT9: 保險 | AU9: 其它 | AV9: 合計
A10: 預計支出/月 | B10: =$J$2 -> 185000 | D10: 生活 | E10: 衣 | M10: 84 | S10: =SUM(F10:R10) -> 84 | V10: =$C$9 -> 202401 | W10: =T9 -> 70147 | X10: =T16 -> 9116 | Y10: =T21 -> 191040 | Z10: =W10+X10+Y10 -> 270303 | AD10: =V10 -> 202401 | AE10: =SUMPRODUCT(($D$9:$D$25=$AE$6)*($E$9:$E$25=AE$9)*$S$9:$S$25) -> 18727 | AF10: =SUMPRODUCT(($D$9:$D$25=$AE$6)*($E$9:$E$25=$AF$9)*$S$9:$S$25) -> 84 | AG10: =SUMPRODUCT(($D$9:$D$25=$AE$6)*($E$9:$E$25=$AG$9)*$S$9:$S$25) -> 5389 | AH10: =SUMPRODUCT(($D$9:$D$25=$AE$6)*($E$9:$E$25=$AH$9)*$S$9:$S$25) -> 3860 | AI10: =SUMPRODUCT(($D$9:$D$25=$AE$6)*($E$9:$E$25=$AI$9)*$S$9:$S$25) -> 28087 | AJ10: =SUMPRODUCT(($D$9:$D$25=$AE$6)*($E$9:$E$25=$AJ$9)*$S$9:$S$25) -> 11700 | AK10: =SUMPRODUCT(($D$9:$D$25=$AE$6)*($E$9:$E$25=$AK$9)*$S$9:$S$25) -> 2300 | AL10: =SUMPRODUCT(($D$9:$D$25=$AL$6)*($E$9:$E$25=$AL$9)*$S$9:$S$25) -> 6020 | AM10: =SUMPRODUCT(($D$9:$D$25=$AL$6)*($E$9:$E$25=$AM$9)*$S$9:$S$25) -> 0 | AN10: =SUMPRODUCT(($D$9:$D$25=$AL$6)*($E$9:$E$25=$AN$9)*$S$9:$S$25) -> 1219 | AO10: =SUMPRODUCT(($D$9:$D$25=$AL$6)*($E$9:$E$25=$AO$9)*$S$9:$S$25) -> 799 | AP10: =SUMPRODUCT(($D$9:$D$25=$AL$6)*($E$9:$E$25=$AP$9)*$S$9:$S$25) -> 1078 | AQ10: =SUMPRODUCT(($D$9:$D$25=$AQ$6)*($E$9:$E$25=$AQ$9)*$S$9:$S$25) -> 178429 | AR10: =SUMPRODUCT(($D$9:$D$25=$AQ$6)*($E$9:$E$25=$AR$9)*$S$9:$S$25) -> 0 | AS10: =SUMPRODUCT(($D$9:$D$25=$AQ$6)*($E$9:$E$25=$AS$9)*$S$9:$S$25) -> 6751 | AT10: =SUMPRODUCT(($D$9:$D$25=$AQ$6)*($E$9:$E$25=$AT$9)*$S$9:$S$25) -> 5860 | AU10: =SUMPRODUCT(($D$9:$D$25=$AQ$6)*($E$9:$E$25=$AU$9)*$S$9:$S$25) -> 0 | AV10: =SUM(AE10:AU10) -> 270303
A11: Total(到本月) | B11: =SUMPRODUCT((($V$10:$V$21)<=VALUE(B9))*($Z$10:$Z$21)) -> 270303 | D11: 生活 | E11: 住 | H11: =241+60+598 -> 899 | Q11: =10500-7000+990 -> 4490 | S11: =SUM(F11:R11) -> 5389 | V11: =$C$28 -> 202402 | W11: =T28 -> 91362 | X11: =T35 -> 9469 | Y11: =T40 -> 55526 | Z11: =W11+X11+Y11 -> 156357 | AD11: =V11 -> 202402 | AE11: =SUMPRODUCT(($D$28:$D$44=$AE$6)*($E$28:$E$44=AE$9)*$S$28:$S$44) -> 25666 | AF11: =SUMPRODUCT(($D$28:$D$44=$AE$6)*($E$28:$E$44=AF$9)*$S$28:$S$44) -> 0 | AG11: =SUMPRODUCT(($D$28:$D$44=$AE$6)*($E$28:$E$44=AG$9)*$S$28:$S$44) -> 4512 | AH11: =SUMPRODUCT(($D$28:$D$44=$AE$6)*($E$28:$E$44=AH$9)*$S$28:$S$44) -> 4665 | AI11: =SUMPRODUCT(($D$28:$D$44=$AE$6)*($E$28:$E$44=AI$9)*$S$28:$S$44) -> 50247 | AJ11: =SUMPRODUCT(($D$28:$D$44=$AE$6)*($E$28:$E$44=AJ$9)*$S$28:$S$44) -> 4672 | AK11: =SUMPRODUCT(($D$28:$D$44=$AE$6)*($E$28:$E$44=AK$9)*$S$28:$S$44) -> 1600 | AL11: =SUMPRODUCT(($D$28:$D$44=$AL$6)*($E$28:$E$44=AL$9)*$S$28:$S$44) -> 5500 | AM11: =SUMPRODUCT(($D$28:$D$44=$AL$6)*($E$28:$E$44=AM$9)*$S$28:$S$44) -> 0 | AN11: =SUMPRODUCT(($D$28:$D$44=$AL$6)*($E$28:$E$44=AN$9)*$S$28:$S$44) -> 2019 | AO11: =SUMPRODUCT(($D$28:$D$44=$AL$6)*($E$28:$E$44=AO$9)*$S$28:$S$44) -> 120 | AP11: =SUMPRODUCT(($D$28:$D$44=$AL$6)*($E$28:$E$44=AP$9)*$S$28:$S$44) -> 1830 | AQ11: =SUMPRODUCT(($D$28:$D$44=$AQ$6)*($E$28:$E$44=AQ$9)*$S$28:$S$44) -> 14523 | AR11: =SUMPRODUCT(($D$28:$D$44=$AQ$6)*($E$28:$E$44=AR$9)*$S$28:$S$44) -> 5052 | AS11: =SUMPRODUCT(($D$28:$D$44=$AQ$6)*($E$28:$E$44=AS$9)*$S$28:$S$44) -> 0 | AT11: =SUMPRODUCT(($D$28:$D$44=$AQ$6)*($E$28:$E$44=AT$9)*$S$28:$S$44) -> 6751 | AU11: =SUMPRODUCT(($D$28:$D$44=$AQ$6)*($E$28:$E$44=AU$9)*$S$28:$S$44) -> 29200 | AV11: =SUM(AE11:AU11) -> 156357
A12: YOY% | B12: =B11/SUMPRODUCT(('2024'!$V$10:$V$21<='2024'!B9)*'2023'!$Z$10:$Z$21) -> 1.2683255 | D12: 生活 | E12: 行 | F12: =100+90+100+100+10 -> 400 | H12: =601+60+598 -> 1259 | M12: 107 | Q12: =596+1498 -> 2094 | S12: =SUM(F12:R12) -> 3860 | V12: =$C$47 -> 202403 | W12: =T47 -> 145225 | X12: =T54 -> 9920 | Y12: =T59 -> 8148 | Z12: =W12+X12+Y12 -> 163293 | AD12: =V12 -> 202403 | AE12: =SUMPRODUCT(($D$47:$D$63=$AE$6)*($E$47:$E$63=AE$9)*$S$47:$S$63) -> 31843 | AF12: =SUMPRODUCT(($D$47:$D$63=$AE$6)*($E$47:$E$63=AF$9)*$S$47:$S$63) -> 3099 | AG12: =SUMPRODUCT(($D$47:$D$63=$AE$6)*($E$47:$E$63=AG$9)*$S$47:$S$63) -> 6520 | AH12: =SUMPRODUCT(($D$47:$D$63=$AE$6)*($E$47:$E$63=AH$9)*$S$47:$S$63) -> 6045 | AI12: =SUMPRODUCT(($D$47:$D$63=$AE$6)*($E$47:$E$63=AI$9)*$S$47:$S$63) -> 84591 | AJ12: =SUMPRODUCT(($D$47:$D$63=$AE$6)*($E$47:$E$63=AJ$9)*$S$47:$S$63) -> 11957 | AK12: =SUMPRODUCT(($D$47:$D$63=$AE$6)*($E$47:$E$63=AK$9)*$S$47:$S$63) -> 1170 | AL12: =SUMPRODUCT(($D$47:$D$63=$AL$6)*($E$47:$E$63=AL$9)*$S$47:$S$63) -> 7600 | AM12: =SUMPRODUCT(($D$47:$D$63=$AL$6)*($E$47:$E$63=AM$9)*$S$47:$S$63) -> 1190 | AN12: =SUMPRODUCT(($D$47:$D$63=$AL$6)*($E$47:$E$63=AN$9)*$S$47:$S$63) -> 350 | AO12: =SUMPRODUCT(($D$47:$D$63=$AL$6)*($E$47:$E$63=AO$9)*$S$47:$S$63) -> 320 | AP12: =SUMPRODUCT(($D$47:$D$63=$AL$6)*($E$47:$E$63=AP$9)*$S$47:$S$63) -> 460 | AQ12: =SUMPRODUCT(($D$47:$D$63=$AQ$6)*($E$47:$E$63=AQ$9)*$S$47:$S$63) -> 1395 | AR12: =SUMPRODUCT(($D$47:$D$63=$AQ$6)*($E$47:$E$63=AR$9)*$S$47:$S$63) -> 0 | AS12: =SUMPRODUCT(($D$47:$D$63=$AQ$6)*($E$47:$E$63=AS$9)*$S$47:$S$63) -> 0 | AT12: =SUMPRODUCT(($D$47:$D$63=$AQ$6)*($E$47:$E$63=AT$9)*$S$47:$S$63) -> 6753 | AU12: =SUMPRODUCT(($D$47:$D$63=$AQ$6)*($E$47:$E$63=AU$9)*$S$47:$S$63) -> 0 | AV12: =SUM(AE12:AU12) -> 163293
A13: Total-旅遊(本月) | B13: =B11-SUMPRODUCT((($AD$10:$AD$21)<=VALUE(B9))*($AQ$10:$AQ$21)) -> 91874 | D13: 生活 | E13: 育-基本 | F13: =11000+3200+3000+2500+2500+5800 -> 28000 | M13: 87 | S13: =SUM(F13:R13) -> 28087 | V13: =$C$66 -> 202404 | W13: =T66 -> 90131 | X13: =T73 -> 7900 | Y13: =T78 -> 41411 | Z13: =W13+X13+Y13 -> 139442 | AD13: =V13 -> 202404 | AE13: =SUMPRODUCT(($D$66:$D$82=$AE$6)*($E$66:$E$82=AE$9)*$S$66:$S$82) -> 32310 | AF13: =SUMPRODUCT(($D$66:$D$82=$AE$6)*($E$66:$E$82=AF$9)*$S$66:$S$82) -> 0 | AG13: =SUMPRODUCT(($D$66:$D$82=$AE$6)*($E$66:$E$82=AG$9)*$S$66:$S$82) -> 8552 | AH13: =SUMPRODUCT(($D$66:$D$82=$AE$6)*($E$66:$E$82=AH$9)*$S$66:$S$82) -> 3289 | AI13: =SUMPRODUCT(($D$66:$D$82=$AE$6)*($E$66:$E$82=AI$9)*$S$66:$S$82) -> 35500 | AJ13: =SUMPRODUCT(($D$66:$D$82=$AE$6)*($E$66:$E$82=AJ$9)*$S$66:$S$82) -> 9580 | AK13: =SUMPRODUCT(($D$66:$D$82=$AE$6)*($E$66:$E$82=AK$9)*$S$66:$S$82) -> 900 | AL13: =SUMPRODUCT(($D$66:$D$82=$AL$6)*($E$66:$E$82=AL$9)*$S$66:$S$82) -> 6090 | AM13: =SUMPRODUCT(($D$66:$D$82=$AL$6)*($E$66:$E$82=AM$9)*$S$66:$S$82) -> 0 | AN13: =SUMPRODUCT(($D$66:$D$82=$AL$6)*($E$66:$E$82=AN$9)*$S$66:$S$82) -> 1070 | AO13: =SUMPRODUCT(($D$66:$D$82=$AL$6)*($E$66:$E$82=AO$9)*$S$66:$S$82) -> 740 | AP13: =SUMPRODUCT(($D$66:$D$82=$AL$6)*($E$66:$E$82=AP$9)*$S$66:$S$82) -> 0 | AQ13: =SUMPRODUCT(($D$66:$D$82=$AQ$6)*($E$66:$E$82=AQ$9)*$S$66:$S$82) -> 9315 | AR13: =SUMPRODUCT(($D$66:$D$82=$AQ$6)*($E$66:$E$82=AR$9)*$S$66:$S$82) -> 0 | AS13: =SUMPRODUCT(($D$66:$D$82=$AQ$6)*($E$66:$E$82=AS$9)*$S$66:$S$82) -> 25115 | AT13: =SUMPRODUCT(($D$66:$D$82=$AQ$6)*($E$66:$E$82=AT$9)*$S$66:$S$82) -> 6751 | AU13: =SUMPRODUCT(($D$66:$D$82=$AQ$6)*($E$66:$E$82=AU$9)*$S$66:$S$82) -> 230 | AV13: =SUM(AE13:AU13) -> 139442
A14: 實際占預計支出% | B14: =B11/($J$2*12) -> 0.12175811 | D14: 生活 | E14: 育-才藝 | F14: =9900+1800 -> 11700 | S14: =SUM(F14:R14) -> 11700 | V14: =$C$85 -> 202405 | W14: =T85 -> 98046 | X14: =T92 -> 15200 | Y14: =T97 -> 60498 | Z14: =W14+X14+Y14 -> 173744 | AD14: =V14 -> 202405 | AE14: =SUMPRODUCT(($D$85:$D$101=$AE$6)*($E$85:$E$101=AE$9)*$S$85:$S$101) -> 29056 | AF14: =SUMPRODUCT(($D$85:$D$101=$AE$6)*($E$85:$E$101=AF$9)*$S$85:$S$101) -> 1000 | AG14: =SUMPRODUCT(($D$85:$D$101=$AE$6)*($E$85:$E$101=AG$9)*$S$85:$S$101) -> 5446 | AH14: =SUMPRODUCT(($D$85:$D$101=$AE$6)*($E$85:$E$101=AH$9)*$S$85:$S$101) -> 6404 | AI14: =SUMPRODUCT(($D$85:$D$101=$AE$6)*($E$85:$E$101=AI$9)*$S$85:$S$101) -> 18840 | AJ14: =SUMPRODUCT(($D$85:$D$101=$AE$6)*($E$85:$E$101=AJ$9)*$S$85:$S$101) -> 37300 | AK14: =SUMPRODUCT(($D$85:$D$101=$AE$6)*($E$85:$E$101=AK$9)*$S$85:$S$101) -> 0 | AL14: =SUMPRODUCT(($D$85:$D$101=$AL$6)*($E$85:$E$101=AL$9)*$S$85:$S$101) -> 6030 | AM14: =SUMPRODUCT(($D$85:$D$101=$AL$6)*($E$85:$E$101=AM$9)*$S$85:$S$101) -> 7370 | AN14: =SUMPRODUCT(($D$85:$D$101=$AL$6)*($E$85:$E$101=AN$9)*$S$85:$S$101) -> 760 | AO14: =SUMPRODUCT(($D$85:$D$101=$AL$6)*($E$85:$E$101=AO$9)*$S$85:$S$101) -> 1040 | AP14: =SUMPRODUCT(($D$85:$D$101=$AL$6)*($E$85:$E$101=AP$9)*$S$85:$S$101) -> 0 | AQ14: =SUMPRODUCT(($D$85:$D$101=$AQ$6)*($E$85:$E$101=AQ$9)*$S$85:$S$101) -> 5300 | AR14: =SUMPRODUCT(($D$85:$D$101=$AQ$6)*($E$85:$E$101=AR$9)*$S$85:$S$101) -> 7920 | AS14: =SUMPRODUCT(($D$85:$D$101=$AQ$6)*($E$85:$E$101=AS$9)*$S$85:$S$101) -> 39527 | AT14: =SUMPRODUCT(($D$85:$D$101=$AQ$6)*($E$85:$E$101=AT$9)*$S$85:$S$101) -> 6751 | AU14: =SUMPRODUCT(($D$85:$D$101=$AQ$6)*($E$85:$E$101=AU$9)*$S$85:$S$101) -> 1000 | AV14: =SUM(AE14:AU14) -> 173744
A15: 預計支出% | B15: =VALUE(RIGHT(B9,2))/12 -> 0.083333333 | D15: 生活 | E15: 醫療費用 | F15: =200 -> 200 | H15: 2100 | S15: =SUM(F15:R15) -> 2300 | V15: =$C$104 -> 202406 | W15: =T104 -> 89519 | X15: =T111 -> 3949 | Y15: =T116 -> 18015 | Z15: =W15+X15+Y15 -> 111483 | AD15: =V15 -> 202406 | AE15: =SUMPRODUCT(($D$104:$D$120=$AE$6)*($E$104:$E$120=AE$9)*$S$104:$S$120) -> 35116 | AF15: =SUMPRODUCT(($D$104:$D$120=$AE$6)*($E$104:$E$120=AF$9)*$S$104:$S$120) -> 5157 | AG15: =SUMPRODUCT(($D$104:$D$120=$AE$6)*($E$104:$E$120=AG$9)*$S$104:$S$120) -> 7267 | AH15: =SUMPRODUCT(($D$104:$D$120=$AE$6)*($E$104:$E$120=AH$9)*$S$104:$S$120) -> 4979 | AI15: =SUMPRODUCT(($D$104:$D$120=$AE$6)*($E$104:$E$120=AI$9)*$S$104:$S$120) -> 22616 | AJ15: =SUMPRODUCT(($D$104:$D$120=$AE$6)*($E$104:$E$120=AJ$9)*$S$104:$S$120) -> 12664 | AK15: =SUMPRODUCT(($D$104:$D$120=$AE$6)*($E$104:$E$120=AK$9)*$S$104:$S$120) -> 1720 | AL15: =SUMPRODUCT(($D$104:$D$120=$AL$6)*($E$104:$E$120=AL$9)*$S$104:$S$120) -> 350 | AM15: =SUMPRODUCT(($D$104:$D$120=$AL$6)*($E$104:$E$120=AM$9)*$S$104:$S$120) -> 0 | AN15: =SUMPRODUCT(($D$104:$D$120=$AL$6)*($E$104:$E$120=AN$9)*$S$104:$S$120) -> 2419 | AO15: =SUMPRODUCT(($D$104:$D$120=$AL$6)*($E$104:$E$120=AO$9)*$S$104:$S$120) -> 540 | AP15: =SUMPRODUCT(($D$104:$D$120=$AL$6)*($E$104:$E$120=AP$9)*$S$104:$S$120) -> 640 | AQ15: =SUMPRODUCT(($D$104:$D$120=$AQ$6)*($E$104:$E$120=AQ$9)*$S$104:$S$120) -> 650 | AR15: =SUMPRODUCT(($D$104:$D$120=$AQ$6)*($E$104:$E$120=AR$9)*$S$104:$S$120) -> 1365 | AS15: =SUMPRODUCT(($D$104:$D$120=$AQ$6)*($E$104:$E$120=AS$9)*$S$104:$S$120) -> 0 | AT15: =SUMPRODUCT(($D$104:$D$120=$AQ$6)*($E$104:$E$120=AT$9)*$S$104:$S$120) -> 0 | AU15: =SUMPRODUCT(($D$104:$D$120=$AQ$6)*($E$104:$E$120=AU$9)*$S$104:$S$120) -> 16000 | AV15: =SUM(AE15:AU15) -> 111483
A16: 剩餘/超支 $$ | B16: =B10*VALUE(RIGHT(B9,2))-B11 -> -85303 | D16: 想要&奢侈品 | E16: N | F16: =4697+423+900 -> 6020 | S16: =SUM(F16:R16) -> 6020 | T16: =SUM(S16:S20) -> 9116 | V16: =$C$123 -> 202407 | W16: =T123 -> 72519 | X16: =T130 -> 36940 | Y16: =T135 -> 29589 | Z16: =W16+X16+Y16 -> 139048 | AD16: =V16 -> 202407 | AE16: =SUMPRODUCT(($D$123:$D$139=$AE$6)*($E$123:$E$139=AE$9)*$S$123:$S$139) -> 35307 | AF16: =SUMPRODUCT(($D$123:$D$139=$AE$6)*($E$123:$E$139=AF$9)*$S$123:$S$139) -> 2400 | AG16: =SUMPRODUCT(($D$123:$D$139=$AE$6)*($E$123:$E$139=AG$9)*$S$123:$S$139) -> 7629 | AH16: =SUMPRODUCT(($D$123:$D$139=$AE$6)*($E$123:$E$139=AH$9)*$S$123:$S$139) -> 9133 | AI16: =SUMPRODUCT(($D$123:$D$139=$AE$6)*($E$123:$E$139=AI$9)*$S$123:$S$139) -> 11000 | AJ16: =SUMPRODUCT(($D$123:$D$139=$AE$6)*($E$123:$E$139=AJ$9)*$S$123:$S$139) -> 7050 | AK16: =SUMPRODUCT(($D$123:$D$139=$AE$6)*($E$123:$E$139=AK$9)*$S$123:$S$139) -> 0 | AL16: =SUMPRODUCT(($D$123:$D$139=$AL$6)*($E$123:$E$139=AL$9)*$S$123:$S$139) -> 36590 | AM16: =SUMPRODUCT(($D$123:$D$139=$AL$6)*($E$123:$E$139=AM$9)*$S$123:$S$139) -> 0 | AN16: =SUMPRODUCT(($D$123:$D$139=$AL$6)*($E$123:$E$139=AN$9)*$S$123:$S$139) -> 0 | AO16: =SUMPRODUCT(($D$123:$D$139=$AL$6)*($E$123:$E$139=AO$9)*$S$123:$S$139) -> 0 | AP16: =SUMPRODUCT(($D$123:$D$139=$AL$6)*($E$123:$E$139=AP$9)*$S$123:$S$139) -> 350 | AQ16: =SUMPRODUCT(($D$123:$D$139=$AQ$6)*($E$123:$E$139=AQ$9)*$S$123:$S$139) -> 18703 | AR16: =SUMPRODUCT(($D$123:$D$139=$AQ$6)*($E$123:$E$139=AR$9)*$S$123:$S$139) -> 4606 | AS16: =SUMPRODUCT(($D$123:$D$139=$AQ$6)*($E$123:$E$139=AS$9)*$S$123:$S$139) -> 6180 | AT16: =SUMPRODUCT(($D$123:$D$139=$AQ$6)*($E$123:$E$139=AT$9)*$S$123:$S$139) -> 0 | AU16: =SUMPRODUCT(($D$123:$D$139=$AQ$6)*($E$123:$E$139=AU$9)*$S$123:$S$139) -> 100 | AV16: =SUM(AE16:AU16) -> 139048
A17: 剩餘/超支 $$(本月) | B17: =$J$2-(S26) -> -85303 | D17: 想要&奢侈品 | E17: A | S17: =SUM(F17:R17) -> 0 | V17: =$C$142 -> 202408 | W17: =T142 -> 28457 | X17: =T149 -> 802 | Y17: =T154 -> 483914.5 | Z17: =W17+X17+Y17 -> 513173.5 | AD17: =V17 -> 202408 | AE17: =SUMPRODUCT(($D$142:$D$158=$AE$6)*($E$142:$E$158=AE$9)*$S$142:$S$158) -> 16810 | AF17: =SUMPRODUCT(($D$142:$D$158=$AE$6)*($E$142:$E$158=AF$9)*$S$142:$S$158) -> 0 | AG17: =SUMPRODUCT(($D$142:$D$158=$AE$6)*($E$142:$E$158=AG$9)*$S$142:$S$158) -> 4799 | AH17: =SUMPRODUCT(($D$142:$D$158=$AE$6)*($E$142:$E$158=AH$9)*$S$142:$S$158) -> 4068 | AI17: =SUMPRODUCT(($D$142:$D$158=$AE$6)*($E$142:$E$158=AI$9)*$S$142:$S$158) -> 2780 | AJ17: =SUMPRODUCT(($D$142:$D$158=$AE$6)*($E$142:$E$158=AJ$9)*$S$142:$S$158) -> 0 | AK17: =SUMPRODUCT(($D$142:$D$158=$AE$6)*($E$142:$E$158=AK$9)*$S$142:$S$158) -> 0 | AL17: =SUMPRODUCT(($D$142:$D$158=$AL$6)*($E$142:$E$158=AL$9)*$S$142:$S$158) -> 0 | AM17: =SUMPRODUCT(($D$142:$D$158=$AL$6)*($E$142:$E$158=AM$9)*$S$142:$S$158) -> 0 | AN17: =SUMPRODUCT(($D$142:$D$158=$AL$6)*($E$142:$E$158=AN$9)*$S$142:$S$158) -> 0 | AO17: =SUMPRODUCT(($D$142:$D$158=$AL$6)*($E$142:$E$158=AO$9)*$S$142:$S$158) -> 0 | AP17: =SUMPRODUCT(($D$142:$D$158=$AL$6)*($E$142:$E$158=AP$9)*$S$142:$S$158) -> 802 | AQ17: =SUMPRODUCT(($D$142:$D$158=$AQ$6)*($E$142:$E$158=AQ$9)*$S$142:$S$158) -> 482895.5 | AR17: =SUMPRODUCT(($D$142:$D$158=$AQ$6)*($E$142:$E$158=AR$9)*$S$142:$S$158) -> 0 | AS17: =SUMPRODUCT(($D$142:$D$158=$AQ$6)*($E$142:$E$158=AS$9)*$S$142:$S$158) -> 0 | AT17: =SUMPRODUCT(($D$142:$D$158=$AQ$6)*($E$142:$E$158=AT$9)*$S$142:$S$158) -> 1019 | AU17: =SUMPRODUCT(($D$142:$D$158=$AQ$6)*($E$142:$E$158=AU$9)*$S$142:$S$158) -> 0 | AV17: =SUM(AE17:AU17) -> 513173.5
D18: 想要&奢侈品 | E18: L | F18: 20 | H18: 1199 | S18: =SUM(F18:R18) -> 1219 | V18: =$C$161 -> 202409 | W18: =T161 -> 115276 | X18: =T168 -> 1900 | Y18: =T173 -> 156326 | Z18: =W18+X18+Y18 -> 273502 | AD18: =V18 -> 202409 | AE18: =SUMPRODUCT(($D$161:$D$177=$AE$6)*($E$161:$E$177=AE$9)*$S$161:$S$177) -> 23248 | AF18: =SUMPRODUCT(($D$161:$D$177=$AE$6)*($E$161:$E$177=AF$9)*$S$161:$S$177) -> 649 | AG18: =SUMPRODUCT(($D$161:$D$177=$AE$6)*($E$161:$E$177=AG$9)*$S$161:$S$177) -> 12200 | AH18: =SUMPRODUCT(($D$161:$D$177=$AE$6)*($E$161:$E$177=AH$9)*$S$161:$S$177) -> 8222 | AI18: =SUMPRODUCT(($D$161:$D$177=$AE$6)*($E$161:$E$177=AI$9)*$S$161:$S$177) -> 59186 | AJ18: =SUMPRODUCT(($D$161:$D$177=$AE$6)*($E$161:$E$177=AJ$9)*$S$161:$S$177) -> 11271 | AK18: =SUMPRODUCT(($D$161:$D$177=$AE$6)*($E$161:$E$177=AK$9)*$S$161:$S$177) -> 500 | AL18: =SUMPRODUCT(($D$161:$D$177=$AL$6)*($E$161:$E$177=AL$9)*$S$161:$S$177) -> 1900 | AM18: =SUMPRODUCT(($D$161:$D$177=$AL$6)*($E$161:$E$177=AM$9)*$S$161:$S$177) -> 0 | AN18: =SUMPRODUCT(($D$161:$D$177=$AL$6)*($E$161:$E$177=AN$9)*$S$161:$S$177) -> 0 | AO18: =SUMPRODUCT(($D$161:$D$177=$AL$6)*($E$161:$E$177=AO$9)*$S$161:$S$177) -> 0 | AP18: =SUMPRODUCT(($D$161:$D$177=$AL$6)*($E$161:$E$177=AP$9)*$S$161:$S$177) -> 0 | AQ18: =SUMPRODUCT(($D$161:$D$177=$AQ$6)*($E$161:$E$177=AQ$9)*$S$161:$S$177) -> 156326 | AR18: =SUMPRODUCT(($D$161:$D$177=$AQ$6)*($E$161:$E$177=AR$9)*$S$161:$S$177) -> 0 | AS18: =SUMPRODUCT(($D$161:$D$177=$AQ$6)*($E$161:$E$177=AS$9)*$S$161:$S$177) -> 0 | AT18: =SUMPRODUCT(($D$161:$D$177=$AQ$6)*($E$161:$E$177=AT$9)*$S$161:$S$177) -> 0 | AU18: =SUMPRODUCT(($D$161:$D$177=$AQ$6)*($E$161:$E$177=AU$9)*$S$161:$S$177) -> 0 | AV18: =SUM(AE18:AU18) -> 273502
D19: 想要&奢侈品 | E19: D | H19: 799 | S19: =SUM(F19:R19) -> 799 | V19: =$C$180 -> 202410 | W19: =T180 -> 73556 | X19: =T187 -> 1605 | Y19: =T192 -> 10666 | Z19: =W19+X19+Y19 -> 85827 | AD19: =V19 -> 202410 | AE19: =SUMPRODUCT(($D$180:$D$196=$AE$6)*($E$180:$E$196=AE$9)*$S$180:$S$196) -> 29203 | AF19: =SUMPRODUCT(($D$180:$D$196=$AE$6)*($E$180:$E$196=AF$9)*$S$180:$S$196) -> 787 | AG19: =SUMPRODUCT(($D$180:$D$196=$AE$6)*($E$180:$E$196=AG$9)*$S$180:$S$196) -> 6581 | AH19: =SUMPRODUCT(($D$180:$D$196=$AE$6)*($E$180:$E$196=AH$9)*$S$180:$S$196) -> 15571 | AI19: =SUMPRODUCT(($D$180:$D$196=$AE$6)*($E$180:$E$196=AI$9)*$S$180:$S$196) -> 11200 | AJ19: =SUMPRODUCT(($D$180:$D$196=$AE$6)*($E$180:$E$196=AJ$9)*$S$180:$S$196) -> 9464 | AK19: =SUMPRODUCT(($D$180:$D$196=$AE$6)*($E$180:$E$196=AK$9)*$S$180:$S$196) -> 750 | AL19: =SUMPRODUCT(($D$180:$D$196=$AL$6)*($E$180:$E$196=AL$9)*$S$180:$S$196) -> 0 | AM19: =SUMPRODUCT(($D$180:$D$196=$AL$6)*($E$180:$E$196=AM$9)*$S$180:$S$196) -> 0 | AN19: =SUMPRODUCT(($D$180:$D$196=$AL$6)*($E$180:$E$196=AN$9)*$S$180:$S$196) -> 0 | AO19: =SUMPRODUCT(($D$180:$D$196=$AL$6)*($E$180:$E$196=AO$9)*$S$180:$S$196) -> 0 | AP19: =SUMPRODUCT(($D$180:$D$196=$AL$6)*($E$180:$E$196=AP$9)*$S$180:$S$196) -> 1605 | AQ19: =SUMPRODUCT(($D$180:$D$196=$AQ$6)*($E$180:$E$196=AQ$9)*$S$180:$S$196) -> 3630 | AR19: =SUMPRODUCT(($D$180:$D$196=$AQ$6)*($E$180:$E$196=AR$9)*$S$180:$S$196) -> 780 | AS19: =SUMPRODUCT(($D$180:$D$196=$AQ$6)*($E$180:$E$196=AS$9)*$S$180:$S$196) -> 0 | AT19: =SUMPRODUCT(($D$180:$D$196=$AQ$6)*($E$180:$E$196=AT$9)*$S$180:$S$196) -> 6256 | AU19: =SUMPRODUCT(($D$180:$D$196=$AQ$6)*($E$180:$E$196=AU$9)*$S$180:$S$196) -> 0 | AV19: =SUM(AE19:AU19) -> 85827
D20: 想要&奢侈品 | E20: 其它 | F20: 200 | H20: 878 | S20: =SUM(F20:R20) -> 1078 | V20: =$C$199 -> 202411 | W20: =T199 -> 61366 | X20: =T206 -> 14122 | Y20: =T211 -> 34828.73 | Z20: =W20+X20+Y20 -> 110316.73 | AD20: =V20 -> 202411 | AE20: =SUMPRODUCT(($D$199:$D$215=$AE$6)*($E$199:$E$215=AE$9)*$S$199:$S$215) -> 24246 | AF20: =SUMPRODUCT(($D$199:$D$215=$AE$6)*($E$199:$E$215=AF$9)*$S$199:$S$215) -> 5545 | AG20: =SUMPRODUCT(($D$199:$D$215=$AE$6)*($E$199:$E$215=AG$9)*$S$199:$S$215) -> 4463 | AH20: =SUMPRODUCT(($D$199:$D$215=$AE$6)*($E$199:$E$215=AH$9)*$S$199:$S$215) -> 7061 | AI20: =SUMPRODUCT(($D$199:$D$215=$AE$6)*($E$199:$E$215=AI$9)*$S$199:$S$215) -> 11494 | AJ20: =SUMPRODUCT(($D$199:$D$215=$AE$6)*($E$199:$E$215=AJ$9)*$S$199:$S$215) -> 7667 | AK20: =SUMPRODUCT(($D$199:$D$215=$AE$6)*($E$199:$E$215=AK$9)*$S$199:$S$215) -> 890 | AL20: =SUMPRODUCT(($D$199:$D$215=$AL$6)*($E$199:$E$215=AL$9)*$S$199:$S$215) -> 0 | AM20: =SUMPRODUCT(($D$199:$D$215=$AL$6)*($E$199:$E$215=AM$9)*$S$199:$S$215) -> 9000 | AN20: =SUMPRODUCT(($D$199:$D$215=$AL$6)*($E$199:$E$215=AN$9)*$S$199:$S$215) -> 2330 | AO20: =SUMPRODUCT(($D$199:$D$215=$AL$6)*($E$199:$E$215=AO$9)*$S$199:$S$215) -> 2592 | AP20: =SUMPRODUCT(($D$199:$D$215=$AL$6)*($E$199:$E$215=AP$9)*$S$199:$S$215) -> 200 | AQ20: =SUMPRODUCT(($D$199:$D$215=$AQ$6)*($E$199:$E$215=AQ$9)*$S$199:$S$215) -> 14252.73 | AR20: =SUMPRODUCT(($D$199:$D$215=$AQ$6)*($E$199:$E$215=AR$9)*$S$199:$S$215) -> 3575 | AS20: =SUMPRODUCT(($D$199:$D$215=$AQ$6)*($E$199:$E$215=AS$9)*$S$199:$S$215) -> 2093 | AT20: =SUMPRODUCT(($D$199:$D$215=$AQ$6)*($E$199:$E$215=AT$9)*$S$199:$S$215) -> 14908 | AU20: =SUMPRODUCT(($D$199:$D$215=$AQ$6)*($E$199:$E$215=AU$9)*$S$199:$S$215) -> 0 | AV20: =SUM(AE20:AU20) -> 110316.73
D21: 一次性支出 | E21: 旅遊 | F21: =360+270+140+150+505+180+170+50+100+100+60+70+30+110+40+100+150+1110+7500+120+100+160+350+300+100+160+330+190+200+150+50+125+807 -> 14337 | H21: =9340+5228+3006+5600+7935+7200+55+95+2860+160 -> 41479 | J21: 7090 | L21: 104295 | M21: =220+100+20+1314+1094 -> 2748 | O21: =7180+1000+300 -> 8480 | S21: =SUM(F21:R21) -> 178429 | T21: =SUM(S21:S25) -> 191040 | V21: =$C$218 -> 202412 | W21: =T218 -> 66002.333 | X21: =T225 -> 15702 | Y21: =T230 -> 3408 | Z21: =W21+X21+Y21 -> 85112.333 | AD21: =V21 -> 202412 | AE21: =SUMPRODUCT(($D$218:$D$234=$AE$6)*($E$218:$E$234=AE$9)*$S$218:$S$234) -> 27969 | AF21: =SUMPRODUCT(($D$218:$D$234=$AE$6)*($E$218:$E$234=AF$9)*$S$218:$S$234) -> 1928 | AG21: =SUMPRODUCT(($D$218:$D$234=$AE$6)*($E$218:$E$234=AG$9)*$S$218:$S$234) -> 6026 | AH21: =SUMPRODUCT(($D$218:$D$234=$AE$6)*($E$218:$E$234=AH$9)*$S$218:$S$234) -> 5418 | AI21: =SUMPRODUCT(($D$218:$D$234=$AE$6)*($E$218:$E$234=AI$9)*$S$218:$S$234) -> 11200 | AJ21: =SUMPRODUCT(($D$218:$D$234=$AE$6)*($E$218:$E$234=AJ$9)*$S$218:$S$234) -> 6710 | AK21: =SUMPRODUCT(($D$218:$D$234=$AE$6)*($E$218:$E$234=AK$9)*$S$218:$S$234) -> 6751.3333 | AL21: =SUMPRODUCT(($D$218:$D$234=$AL$6)*($E$218:$E$234=AL$9)*$S$218:$S$234) -> 3382 | AM21: =SUMPRODUCT(($D$218:$D$234=$AL$6)*($E$218:$E$234=AM$9)*$S$218:$S$234) -> 3950 | AN21: =SUMPRODUCT(($D$218:$D$234=$AL$6)*($E$218:$E$234=AN$9)*$S$218:$S$234) -> 2000 | AO21: =SUMPRODUCT(($D$218:$D$234=$AL$6)*($E$218:$E$234=AO$9)*$S$218:$S$234) -> 2000 | AP21: =SUMPRODUCT(($D$218:$D$234=$AL$6)*($E$218:$E$234=AP$9)*$S$218:$S$234) -> 4370 | AQ21: =SUMPRODUCT(($D$218:$D$234=$AQ$6)*($E$218:$E$234=AQ$9)*$S$218:$S$234) -> 1000 | AR21: =SUMPRODUCT(($D$218:$D$234=$AQ$6)*($E$218:$E$234=AR$9)*$S$218:$S$234) -> 2408 | AS21: =SUMPRODUCT(($D$218:$D$234=$AQ$6)*($E$218:$E$234=AS$9)*$S$218:$S$234) -> 0 | AT21: =SUMPRODUCT(($D$218:$D$234=$AQ$6)*($E$218:$E$234=AT$9)*$S$218:$S$234) -> 0 | AU21: =SUMPRODUCT(($D$218:$D$234=$AQ$6)*($E$218:$E$234=AU$9)*$S$218:$S$234) -> 0 | AV21: =SUM(AE21:AU21) -> 85112.333
D22: 一次性支出 | E22: 家庭聚會 | S22: =SUM(F22:R22) -> 0
D23: 一次性支出 | E23: 稅費 | Q23: 6751 | S23: =SUM(F23:R23) -> 6751
D24: 一次性支出 | E24: 保險 | H24: 5860 | S24: =SUM(F24:R24) -> 5860
D25: 一次性支出 | E25: 其它 | S25: =SUM(F25:R25) -> 0
D26: Total | E26: Total | F26: =SUM(F9:F25) -> 64651 | G26: =SUM(G9:G25) -> 0 | H26: =SUM(H9:H25) -> 58410 | I26: =SUM(I9:I25) -> 420 | J26: =SUM(J9:J25) -> 7090 | K26: =SUM(K9:K25) -> 0 | L26: =SUM(L9:L25) -> 104295 | M26: =SUM(M9:M25) -> 4382 | ... S26: =SUM(S9:S25) -> 270303
A28: 月份 | B28: =B9+1 -> 202402 | C28: 202402 | D28: 生活 | E28: 食 | F28: =199+60+55+900+1055+175+330+1290+570+55+95+95+620+192 -> 5691 | H28: =500+120+500+48+114+49+49+541+59+20+48+319+20+275+180+75+117+125+155+79+280+1381 -> 5054 | I28: =114+280+150+173+75+110+180+145+350+90+75+30 -> 1772 | J28: 68 | L28: 10 | M28: =949+760+310+116+77+80+120+95+590+460+130+650 -> 4337 | O28: =280+299+155 -> 734 | Q28: =2000+2000+0+2000+2000 -> 8000 | S28: =SUM(F28:R28) -> 25666 | T28: =SUM(S28:S34) -> 91362
A29: 預計支出/月 | B29: =$J$2 -> 185000 | D29: 生活 | E29: 衣 | S29: =SUM(F29:R29) -> 0
A30: Total(到本月) | B30: =SUMPRODUCT((($V$10:$V$21)<=VALUE(B28))*($Z$10:$Z$21)) -> 426660 | D30: 生活 | E30: 住 | H30: =185+827 -> 1012 | Q30: =10500-7000 -> 3500 | S30: =SUM(F30:R30) -> 4512
A31: YOY% | B31: =B30/SUMPRODUCT(('2024'!$V$10:$V$21<='2024'!B28)*'2023'!$Z$10:$Z$21) -> 1.0489464 | D31: 生活 | E31: 行 | F31: =38+40+100+100+300+50 -> 628 | H31: =591+64+175+500+400 -> 1730 | I31: =38+599 -> 637 | Q31: =596+1074 -> 1670 | S31: =SUM(F31:R31) -> 4665
A32: Total-旅遊(本月) | B32: =B30-SUMPRODUCT((($AD$10:$AD$21)<=VALUE(B28))*($AQ$10:$AQ$21)) -> 233708 | D32: 生活 | E32: 育-基本 | F32: =36000+11000+6795+2000-5000-548 -> 50247 | S32: =SUM(F32:R32) -> 50247
A33: 實際占預計支出% | B33: =B30/($J$2*12) -> 0.19218919 | D33: 生活 | E33: 育-才藝 | F33: =1800+2872 -> 4672 | S33: =SUM(F33:R33) -> 4672
A34: 支出% | B34: =VALUE(RIGHT(B28,2))/12 -> 0.16666667 | D34: 生活 | E34: 醫療費用 | F34: 1600 | S34: =SUM(F34:R34) -> 1600
A35: 剩餘/超支 $$ | B35: =B29*VALUE(RIGHT(B28,2))-B30 -> -56660 | D35: 想要&奢侈品 | E35: N | F35: 5500 | S35: =SUM(F35:R35) -> 5500 | T35: =SUM(S35:S39) -> 9469
A36: 剩餘/超支 $$(本月) | B36: =$J$2-(S45) -> 28643 | D36: 想要&奢侈品 | E36: A | S36: =SUM(G36:R36) -> 0
D37: 想要&奢侈品 | E37: L | F37: =499+900+60+60 -> 1519 | O37: 500 | S37: =SUM(F37:R37) -> 2019
D38: 想要&奢侈品 | E38: D | F38: =60+60 -> 120 | S38: =SUM(F38:R38) -> 120
D39: 想要&奢侈品 | E39: 其它 | F39: 480 | H39: 1350 | S39: =SUM(F39:R39) -> 1830
D40: 一次性支出 | E40: 旅遊 | F40: =345+355+130+100+80+60+75+40+45+40+100+70+190+275+40+300+100+40+150+50+200+60+205+100+100+100+200+180+300+60+400+40+80 -> 4610 | H40: =2853+43+78+145+1050+55+50+23+250+78+40+60+108+145+400+120+100 -> 5598 | M40: =1400+1139+126+1300 -> 3965 | O40: 350 | S40: =SUM(F40:R40) -> 14523 | T40: =SUM(S40:S44) -> 55526
D41: 一次性支出 | E41: 家庭聚會 | H41: 835 | M41: 2717 | O41: 1500 | S41: =SUM(F41:R41) -> 5052
...

Sheet 2023
A1: 生活 | B1: =SUMIF(D:D,A1,S:S) -> 1046214 | C1: =B1/$B$4 -> 0.45365168 | J1: 月支出估計 | K1: 車貸 | L1: 年支出估計
A2: 想要&奢侈品 | B2: =SUMIF(D:D,A2,S:S) -> 164570 | C2: =B2/$B$4 -> 0.071359642 | J2: 160000 | K2: =27778*9 -> 250002 | L2: =J2*12+K2 -> 2170002
A3: 一次性支出 | B3: =SUMIF(D:D,A3,S:S) -> 1095421.5 | C3: =B3/$B$4 -> 0.47498868 | AD3: 202212 | AS3: =27778*12 -> 333336
A4: Total | B4: =SUMIF(D:D,A4,S:S) -> 2306205.5 | C4: =B4-B89 -> 1462985.5 | AD4: 202312 | AE4: =AE5/$AD$5 -> 0.14157238 | AF4: =AF5/$AD$5 -> 0.0042589439 | AG4: =AG5/$AD$5 -> 0.057611952 | AH4: =AH5/$AD$5 -> 0.0042624128 | AI4: =AI5/$AD$5 -> 0.11898376 | AJ4: =AJ5/$AD$5 -> 0.093405379 | AK4: =AK5/$AD$5 -> 0.033556853 | AL4: =AL5/$AD$5 -> 0.014894596 | ... AU4: =AU5/$AD$5 -> 0.055091361
A5: Total-車貸 | B5: =B4-K2 -> 2056203.5 | AD5: =SUM(AE5:AU5) -> 2306205.5 | AE5: =SUM(AE10:AE21) -> 326495 | AF5: =SUM(AF10:AF21) -> 9822 | AG5: =SUM(AG10:AG21) -> 132865 | AH5: =SUM(AH10:AH21) -> 9830 | AI5: =SUM(AI10:AI21) -> 274401 | AJ5: =SUM(AJ10:AJ21) -> 215412 | AK5: =SUM(AK10:AK21) -> 77389 | AL5: =SUM(AL10:AL21) -> 34350 | ... AU5: =SUM(AU10:AU21) -> 127052
A6: 占預計支出比例 | B6: =B4/L2 -> 1.0627665 | F6: =F7/$S$7 -> 0.47703511 | G6: =G7/$S$7 -> 0 | H6: =H7/$S$7 -> 0.21227857 | I6: =I7/$S$7 -> 0.015369402 | J6: =J7/$S$7 -> 0.0024906714 | K6: =K7/$S$7 -> 0 | L6: =L7/$S$7 -> 0.0093166025 | M6: =M7/$S$7 -> 0.10376395 | ... R6: =R7/$S$7 -> 0 | AE6: =W9 -> 生活 | AL6: =X9 -> 想要&奢侈品 | AQ6: =Y9 -> 一次性支出
F7: =SUMIF($D$9:$D$1012,"Total",F9:F1012) -> 1100141 | G7: =SUMIF($D$9:$D$1012,"Total",G9:G1012) -> 0 | H7: =SUMIF($D$9:$D$1012,"Total",H9:H1012) -> 489558 | I7: =SUMIF($D$9:$D$1012,"Total",I9:I1012) -> 35445 | J7: =SUMIF($D$9:$D$1012,"Total",J9:J1012) -> 5744 | K7: =SUMIF($D$9:$D$1012,"Total",K9:K1012) -> 0 | L7: =SUMIF($D$9:$D$1012,"Total",L9:L1012) -> 21486 | M7: =SUMIF($D$9:$D$1012,"Total",M9:M1012) -> 239301 | ... R7: =SUMIF($D$9:$D$1012,"Total",R9:R1012) -> 0 | S7: =SUM(F7:R7) -> 2306205.5 | AD7: YOY% | AE7: =SUMPRODUCT((VALUE($AD$10:$AD$21)<=VALUE($AD$4))*(AE10:AK21))/SUMPRODUCT((VALUE('2022'!$AD$10:$AD$21)<=VALUE($AD$3))*('2022'!AE$10:AK$21)) -> 0.98418014 | AL7: =SUMPRODUCT((VALUE($AD$10:$AD$21)<=VALUE($AD$4))*(AL10:AP21))/SUMPRODUCT((VALUE('2022'!$AD$10:$AD$21)<=VALUE($AD$3))*('2022'!AL$10:AP$21)) -> 0.89785207 | AQ7: =SUMPRODUCT((VALUE($AD$10:$AD$21)<=VALUE($AD$4))*(AQ10:AU21))/SUMPRODUCT((VALUE('2022'!$AD$10:$AD$21)<=VALUE($AD$3))*('2022'!AQ$10:AU$21)) -> 1.6291606
C8: 年月 | F8: 其他現金支出 | G8: 渣打現金回饋 | H8: 台新ALL | I8: 玉山ALL | J8: 樂天 | K8: 花旗 | L8: 國泰KOKO&COSTCO | M8: 合庫+永豐+星展 | N8: 聯邦微風卡 | O8: 王董Creditcard | P8: 永豐三井卡 | Q8: 孝敬長輩 | S8: Total | W8: =SUM(W10:W21) -> 1046214 | X8: =SUM(X10:X21) -> 164570 | Y8: =SUM(Y10:Y21) -> 1095421.5 | AD8: =SUMPRODUCT((VALUE($AD$10:$AD$21)<=VALUE($AD$4))*(AE10:AU21))/SUMPRODUCT((VALUE('2022'!$AD$10:$AD$21)<=VALUE($AD$3))*('2022'!AE$10:AU$21)) -> 1.2019575 | AE8: =SUMPRODUCT((VALUE($AD$10:$AD$21)<=VALUE($AD$4))*(AE10:AE21))/SUMPRODUCT((VALUE('2022'!$AD$10:$AD$21)<=VALUE($AD$3))*('2022'!AG$10:AG$21)) -> 1.0648926 | AF8: =(SUMPRODUCT((VALUE($AD$10:$AD$21)<=VALUE($AD$4))*(AF10:AF21))+SUMPRODUCT((VALUE($AD$10:$AD$21)<=VALUE($AD$4))*(AG10:AG21))+SUMPRODUCT((VALUE($AD$10:$AD$21)<=VALUE($AD$4))*(AK10:AK21)))/(SUMPRODUCT((VALUE('2022'!$AD$10:$AD$21)<=VALUE($AD$3))*('2022'!AE$10:AE$21))+SUMPRODUCT((VALUE('2022'!$AD$10:$AD$21)<=VALUE($AD$3))*('2022'!AI$10:AI$21))+SUMPRODUCT((VALUE('2022'!$AD$10:$AD$21)<=VALUE($AD$3))*('2022'!AJ$10:AJ$21))) -> 0.8796636 | AI8: =(SUMPRODUCT((VALUE($AD$10:$AD$21)<=VALUE($AD$4))*(AI10:AI21))+SUMPRODUCT((VALUE($AD$10:$AD$21)<=VALUE($AD$4))*(AJ10:AJ21)))/SUMPRODUCT((VALUE('2022'!$AD$10:$AD$21)<=VALUE($AD$3))*('2022'!AK$10:AK$21)) -> 1.0524175 | AK8: =SUMPRODUCT((VALUE($AD$10:$AD$21)<=VALUE($AD$4))*(AH10:AH21))/SUMPRODUCT((VALUE('2022'!$AD$10:$AD$21)<=VALUE($AD$3))*('2022'!AF$10:AF$21)) -> 0.24073666 | AL8: =SUMPRODUCT((VALUE($AD$10:$AD$21)<=VALUE($AD$4))*(AL10:AL21))/SUMPRODUCT((VALUE('2022'!$AD$10:$AD$21)<=VALUE($AD$3))*('2022'!AL10:AL21)) -> 0.42894605 | AM8: =SUMPRODUCT((VALUE($AD$10:$AD$21)<=VALUE($AD$4))*(AM10:AM21))/SUMPRODUCT((VALUE('2022'!$AD$10:$AD$21)<=VALUE($AD$3))*('2022'!AM10:AM21)) -> 1.0548921 | AN8: =SUMPRODUCT((VALUE($AD$10:$AD$21)<=VALUE($AD$4))*(AN10:AN21))/SUMPRODUCT((VALUE('2022'!$AD$10:$AD$21)<=VALUE($AD$3))*('2022'!AN10:AN21)) -> 1.0116222 | AO8: =SUMPRODUCT((VALUE($AD$10:$AD$21)<=VALUE($AD$4))*(AO10:AO21))/SUMPRODUCT((VALUE('2022'!$AD$10:$AD$21)<=VALUE($AD$3))*('2022'!AO10:AO21)) -> 0.54366013 | AP8: =SUMPRODUCT((VALUE($AD$10:$AD$21)<=VALUE($AD$4))*(AP10:AP21))/SUMPRODUCT((VALUE('2022'!$AD$10:$AD$21)<=VALUE($AD$3))*('2022'!AP10:AP21)) -> 3.4068037 | AQ8: =SUMPRODUCT((VALUE($AD$10:$AD$21)<=VALUE($AD$4))*(AQ10:AQ21))/SUMPRODUCT((VALUE('2022'!$AD$10:$AD$21)<=VALUE($AD$3))*('2022'!AQ10:AQ21)) -> 4.3633861 | AR8: =SUMPRODUCT((VALUE($AD$10:$AD$21)<=VALUE($AD$4))*(AR10:AR21))/SUMPRODUCT((VALUE('2022'!$AD$10:$AD$21)<=VALUE($AD$3))*('2022'!AR10:AR21)) -> 1.5273838 | AS8: =SUMPRODUCT((VALUE($AD$10:$AD$21)<=VALUE($AD$4))*(AS10:AS21))/SUMPRODUCT((VALUE('2022'!$AD$10:$AD$21)<=VALUE($AD$3))*('2022'!AS10:AS21)) -> 0.90092511 | ... AU8: =SUMPRODUCT((VALUE($AD$10:$AD$21)<=VALUE($AD$4))*(AU10:AU21))/SUMPRODUCT((VALUE('2022'!$AD$10:$AD$21)<=VALUE($AD$3))*('2022'!AU10:AU21)) -> 1.3495926
A9: 月份 | B9: 202301 | C9: 202301 | D9: 生活 | E9: 食 | F9: =20+1224+30+1030+80+480+340+100+260+355+170+313+52+12+45+340+100+150+100+40+100+90 -> 5431 | H9: =19+104+39+55+109+68+38+202+500+500+175+39+1232+55+105+100+165+15+109+18+47+60+12+80+500+404+368+560+56+55+75 -> 5864 | I9: =69+38+125+65+3+200+55+1628+60+55+56+315+203 -> 2872 | J9: 1100 | M9: 237 | N9: =50+50+77+254 -> 431 | O9: =65+199+56+400 -> 720 | P9: =638+180+230 -> 1048 | Q9: =2000+2000+2000+2000 -> 8000 | S9: =SUM(F9:R9) -> 25703 | T9: =SUM(S9:S15) -> 79200 | V9: 月份 | W9: =A1 -> 生活 | X9: 想要&奢侈品 | Y9: =A3 -> 一次性支出 | Z9: Total | AD9: 月份 | AE9: 食 | AF9: 衣 | AG9: 住 | AH9: 醫療費用 | AI9: 育-基本 | AJ9: 育-才藝 | AK9: 行 | AL9: N | AM9: A | AN9: L | AO9: D | AP9: 其它 | AQ9: 旅遊 | AR9: 家庭聚會 | AS9: 稅費 | AT9: 保險 | AU9: 其它 | AV9: 合計
A10: 預計支出/月 | B10: =$J$2 -> 160000 | D10: 生活 | E10: 衣 | H10: 990 | I10: 1040 | J10: 790 | S10: =SUM(F10:R10) -> 2820 | V10: =$C$9 -> 202301 | W10: =T9 -> 79200 | X10: =T16 -> 47777 | Y10: =T21 -> 86141 | Z10: =W10+X10+Y10 -> 213118 | AA10: =W10/'2022'!W10-1 -> -0.10718312 | AB10: =X10/'2022'!X10-1 -> 1.8253696 | AC10: =Y10/'2022'!Y10-1 -> 0.75300678 | AD10: =V10 -> 202301 | AE10: =SUMPRODUCT(($D$9:$D$25=$AE$6)*($E$9:$E$25=AE$9)*$S$9:$S$25) -> 25703 | AF10: =SUMPRODUCT(($D$9:$D$25=$AE$6)*($E$9:$E$25=$AF$9)*$S$9:$S$25) -> 2820 | AG10: =SUMPRODUCT(($D$9:$D$25=$AE$6)*($E$9:$E$25=$AG$9)*$S$9:$S$25) -> 10108 | AH10: =SUMPRODUCT(($D$9:$D$25=$AE$6)*($E$9:$E$25=$AH$9)*$S$9:$S$25) -> 1080 | AI10: =SUMPRODUCT(($D$9:$D$25=$AE$6)*($E$9:$E$25=$AI$9)*$S$9:$S$25) -> 18169 | AJ10: =SUMPRODUCT(($D$9:$D$25=$AE$6)*($E$9:$E$25=$AJ$9)*$S$9:$S$25) -> 15220 | AK10: =SUMPRODUCT(($D$9:$D$25=$AE$6)*($E$9:$E$25=$AK$9)*$S$9:$S$25) -> 6100 | AL10: =SUMPRODUCT(($D$9:$D$25=$AL$6)*($E$9:$E$25=$AL$9)*$S$9:$S$25) -> 489 | AM10: =SUMPRODUCT(($D$9:$D$25=$AL$6)*($E$9:$E$25=$AM$9)*$S$9:$S$25) -> 46498 | AN10: =SUMPRODUCT(($D$9:$D$25=$AL$6)*($E$9:$E$25=$AN$9)*$S$9:$S$25) -> 150 | AO10: =SUMPRODUCT(($D$9:$D$25=$AL$6)*($E$9:$E$25=$AO$9)*$S$9:$S$25) -> 350 | AP10: =SUMPRODUCT(($D$9:$D$25=$AL$6)*($E$9:$E$25=$AP$9)*$S$9:$S$25) -> 290 | AQ10: =SUMPRODUCT(($D$9:$D$25=$AQ$6)*($E$9:$E$25=$AQ$9)*$S$9:$S$25) -> 39981 | AR10: =SUMPRODUCT(($D$9:$D$25=$AQ$6)*($E$9:$E$25=$AR$9)*$S$9:$S$25) -> 1800 | AS10: =SUMPRODUCT(($D$9:$D$25=$AQ$6)*($E$9:$E$25=$AS$9)*$S$9:$S$25) -> 27778 | AT10: =SUMPRODUCT(($D$9:$D$25=$AQ$6)*($E$9:$E$25=$AT$9)*$S$9:$S$25) -> 6753 | AU10: =SUMPRODUCT(($D$9:$D$25=$AQ$6)*($E$9:$E$25=$AU$9)*$S$9:$S$25) -> 9829 | AV10: =SUM(AE10:AU10) -> 213118
A11: Total(到本月) | B11: =SUMPRODUCT((($V$10:$V$21)<=VALUE(B9))*($Z$10:$Z$21)) -> 213118 | D11: 生活 | E11: 住 | F11: 3028 | H11: =303+0 -> 303 | Q11: =10500-6000+1497+1580-800 -> 6777 | S11: =SUM(F11:R11) -> 10108 | V11: =$C$28 -> 202302 | W11: =T28 -> 89755 | X11: =T35 -> 2218 | Y11: =T40 -> 101660 | Z11: =W11+X11+Y11 -> 193633 | AA11: =W11/'2022'!W11-1 -> -0.24704708 | AB11: =X11/'2022'!X11-1 -> -0.81834562 | AC11: =Y11/'2022'!Y11-1 -> 1.0916404 | AD11: =V11 -> 202302 | AE11: =SUMPRODUCT(($D$28:$D$44=$AE$6)*($E$28:$E$44=AE$9)*$S$28:$S$44) -> 22683 | AF11: =SUMPRODUCT(($D$28:$D$44=$AE$6)*($E$28:$E$44=AF$9)*$S$28:$S$44) -> 0 | AG11: =SUMPRODUCT(($D$28:$D$44=$AE$6)*($E$28:$E$44=AG$9)*$S$28:$S$44) -> 8367 | AH11: =SUMPRODUCT(($D$28:$D$44=$AE$6)*($E$28:$E$44=AH$9)*$S$28:$S$44) -> 80 | AI11: =SUMPRODUCT(($D$28:$D$44=$AE$6)*($E$28:$E$44=AI$9)*$S$28:$S$44) -> 45531 | AJ11: =SUMPRODUCT(($D$28:$D$44=$AE$6)*($E$28:$E$44=AJ$9)*$S$28:$S$44) -> 6915 | AK11: =SUMPRODUCT(($D$28:$D$44=$AE$6)*($E$28:$E$44=AK$9)*$S$28:$S$44) -> 6179 | AL11: =SUMPRODUCT(($D$28:$D$44=$AL$6)*($E$28:$E$44=AL$9)*$S$28:$S$44) -> 40 | AM11: =SUMPRODUCT(($D$28:$D$44=$AL$6)*($E$28:$E$44=AM$9)*$S$28:$S$44) -> 40 | AN11: =SUMPRODUCT(($D$28:$D$44=$AL$6)*($E$28:$E$44=AN$9)*$S$28:$S$44) -> 969 | AO11: =SUMPRODUCT(($D$28:$D$44=$AL$6)*($E$28:$E$44=AO$9)*$S$28:$S$44) -> 1069 | AP11: =SUMPRODUCT(($D$28:$D$44=$AL$6)*($E$28:$E$44=AP$9)*$S$28:$S$44) -> 100 | AQ11: =SUMPRODUCT(($D$28:$D$44=$AQ$6)*($E$28:$E$44=AQ$9)*$S$28:$S$44) -> 61076 | AR11: =SUMPRODUCT(($D$28:$D$44=$AQ$6)*($E$28:$E$44=AR$9)*$S$28:$S$44) -> 0 | AS11: =SUMPRODUCT(($D$28:$D$44=$AQ$6)*($E$28:$E$44=AS$9)*$S$28:$S$44) -> 27778 | AT11: =SUMPRODUCT(($D$28:$D$44=$AQ$6)*($E$28:$E$44=AT$9)*$S$28:$S$44) -> 9117 | AU11: =SUMPRODUCT(($D$28:$D$44=$AQ$6)*($E$28:$E$44=AU$9)*$S$28:$S$44) -> 3689 | AV11: =SUM(AE11:AU11) -> 193633
A12: YOY% | B12: =B11/SUMPRODUCT(('2023'!$V$10:$V$21<='2023'!B9)*'2022'!$Z$10:$Z$21) -> 1.3771138 | D12: 生活 | E12: 行 | F12: =60+80+40+35+100+80 -> 395 | H12: =1441+724+110+69+45 -> 2389 | I12: =1249+1430 -> 2679 | O12: 40 | Q12: 597 | S12: =SUM(F12:R12) -> 6100 | V12: =$C$47 -> 202303 | W12: =T47 -> 106277 | X12: =T54 -> 4371 | Y12: =T59 -> 77572 | Z12: =W12+X12+Y12 -> 188220 | AA12: =W12/'2022'!W12-1 -> 0.31311546 | AB12: =X12/'2022'!X12-1 -> -0.55434339 | AC12: =Y12/'2022'!Y12-1 -> 0.46844357 | AD12: =V12 -> 202303 | AE12: =SUMPRODUCT(($D$47:$D$63=$AE$6)*($E$47:$E$63=AE$9)*$S$47:$S$63) -> 30473 | AF12: =SUMPRODUCT(($D$47:$D$63=$AE$6)*($E$47:$E$63=AF$9)*$S$47:$S$63) -> 400 | AG12: =SUMPRODUCT(($D$47:$D$63=$AE$6)*($E$47:$E$63=AG$9)*$S$47:$S$63) -> 11354 | AH12: =SUMPRODUCT(($D$47:$D$63=$AE$6)*($E$47:$E$63=AH$9)*$S$47:$S$63) -> 570 | AI12: =SUMPRODUCT(($D$47:$D$63=$AE$6)*($E$47:$E$63=AI$9)*$S$47:$S$63) -> 22135 | AJ12: =SUMPRODUCT(($D$47:$D$63=$AE$6)*($E$47:$E$63=AJ$9)*$S$47:$S$63) -> 37083 | AK12: =SUMPRODUCT(($D$47:$D$63=$AE$6)*($E$47:$E$63=AK$9)*$S$47:$S$63) -> 4262 | AL12: =SUMPRODUCT(($D$47:$D$63=$AL$6)*($E$47:$E$63=AL$9)*$S$47:$S$63) -> 500 | AM12: =SUMPRODUCT(($D$47:$D$63=$AL$6)*($E$47:$E$63=AM$9)*$S$47:$S$63) -> 610 | AN12: =SUMPRODUCT(($D$47:$D$63=$AL$6)*($E$47:$E$63=AN$9)*$S$47:$S$63) -> 1618 | AO12: =SUMPRODUCT(($D$47:$D$63=$AL$6)*($E$47:$E$63=AO$9)*$S$47:$S$63) -> 1445 | AP12: =SUMPRODUCT(($D$47:$D$63=$AL$6)*($E$47:$E$63=AP$9)*$S$47:$S$63) -> 198 | AQ12: =SUMPRODUCT(($D$47:$D$63=$AQ$6)*($E$47:$E$63=AQ$9)*$S$47:$S$63) -> 26432 | AR12: =SUMPRODUCT(($D$47:$D$63=$AQ$6)*($E$47:$E$63=AR$9)*$S$47:$S$63) -> 840 | AS12: =SUMPRODUCT(($D$47:$D$63=$AQ$6)*($E$47:$E$63=AS$9)*$S$47:$S$63) -> 27778 | AT12: =SUMPRODUCT(($D$47:$D$63=$AQ$6)*($E$47:$E$63=AT$9)*$S$47:$S$63) -> 6753 | AU12: =SUMPRODUCT(($D$47:$D$63=$AQ$6)*($E$47:$E$63=AU$9)*$S$47:$S$63) -> 15769 | AV12: =SUM(AE12:AU12) -> 188220
A13: Total-車貸(本月) | B13: =B11-$K$2*VALUE(RIGHT(B9,2))/9 -> 185340 | D13: 生活 | E13: 育-基本 | F13: =3200+3000+100+11500+65 -> 17865 | H13: =60*2+5*2+174 -> 304 | S13: =SUM(F13:R13) -> 18169 | V13: =$C$66 -> 202304 | W13: =T66 -> 83077 | X13: =T73 -> 9891 | Y13: =T78 -> 93830 | Z13: =W13+X13+Y13 -> 186798 | AA13: =W13/'2022'!W13-1 -> 0.1266664 | AB13: =X13/'2022'!X13-1 -> 2.6837989 | AC13: =Y13/'2022'!Y13-1 -> 0.74185045 | AD13: =V13 -> 202304 | AE13: =SUMPRODUCT(($D$66:$D$82=$AE$6)*($E$66:$E$82=AE$9)*$S$66:$S$82) -> 37200 | AF13: =SUMPRODUCT(($D$66:$D$82=$AE$6)*($E$66:$E$82=AF$9)*$S$66:$S$82) -> 0 | AG13: =SUMPRODUCT(($D$66:$D$82=$AE$6)*($E$66:$E$82=AG$9)*$S$66:$S$82) -> 11249 | AH13: =SUMPRODUCT(($D$66:$D$82=$AE$6)*($E$66:$E$82=AH$9)*$S$66:$S$82) -> 660 | AI13: =SUMPRODUCT(($D$66:$D$82=$AE$6)*($E$66:$E$82=AI$9)*$S$66:$S$82) -> 16000 | AJ13: =SUMPRODUCT(($D$66:$D$82=$AE$6)*($E$66:$E$82=AJ$9)*$S$66:$S$82) -> 14950 | AK13: =SUMPRODUCT(($D$66:$D$82=$AE$6)*($E$66:$E$82=AK$9)*$S$66:$S$82) -> 3018 | AL13: =SUMPRODUCT(($D$66:$D$82=$AL$6)*($E$66:$E$82=AL$9)*$S$66:$S$82) -> 762 | AM13: =SUMPRODUCT(($D$66:$D$82=$AL$6)*($E$66:$E$82=AM$9)*$S$66:$S$82) -> 1850 | AN13: =SUMPRODUCT(($D$66:$D$82=$AL$6)*($E$66:$E$82=AN$9)*$S$66:$S$82) -> 6889 | AO13: =SUMPRODUCT(($D$66:$D$82=$AL$6)*($E$66:$E$82=AO$9)*$S$66:$S$82) -> 390 | AP13: =SUMPRODUCT(($D$66:$D$82=$AL$6)*($E$66:$E$82=AP$9)*$S$66:$S$82) -> 0 | AQ13: =SUMPRODUCT(($D$66:$D$82=$AQ$6)*($E$66:$E$82=AQ$9)*$S$66:$S$82) -> 36242 | AR13: =SUMPRODUCT(($D$66:$D$82=$AQ$6)*($E$66:$E$82=AR$9)*$S$66:$S$82) -> 0 | AS13: =SUMPRODUCT(($D$66:$D$82=$AQ$6)*($E$66:$E$82=AS$9)*$S$66:$S$82) -> 39008 | AT13: =SUMPRODUCT(($D$66:$D$82=$AQ$6)*($E$66:$E$82=AT$9)*$S$66:$S$82) -> 6751 | AU13: =SUMPRODUCT(($D$66:$D$82=$AQ$6)*($E$66:$E$82=AU$9)*$S$66:$S$82) -> 11829 | AV13: =SUM(AE13:AU13) -> 186798
A14: 實際占預計支出% | B14: =B13/($J$2*12) -> 0.09653125 | D14: 生活 | E14: 育-才藝 | F14: 15050 | H14: 170 | S14: =SUM(F14:R14) -> 15220 | V14: =$C$85 -> 202305 | W14: =T85 -> 75189 | X14: =T92 -> 16920 | Y14: =T97 -> 108232 | Z14: =W14+X14+Y14 -> 200341 | AA14: =W14/'2022'!W14-1 -> 0.037647838 | AB14: =X14/'2022'!X14-1 -> 2.8480782 | AC14: =Y14/'2022'!Y14-1 -> 0.57977551 | AD14: =V14 -> 202305 | AE14: =SUMPRODUCT(($D$85:$D$101=$AE$6)*($E$85:$E$101=AE$9)*$S$85:$S$101) -> 28770 | AF14: =SUMPRODUCT(($D$85:$D$101=$AE$6)*($E$85:$E$101=AF$9)*$S$85:$S$101) -> 3630 | AG14: =SUMPRODUCT(($D$85:$D$101=$AE$6)*($E$85:$E$101=AG$9)*$S$85:$S$101) -> 8913 | AH14: =SUMPRODUCT(($D$85:$D$101=$AE$6)*($E$85:$E$101=AH$9)*$S$85:$S$101) -> 5010 | AI14: =SUMPRODUCT(($D$85:$D$101=$AE$6)*($E$85:$E$101=AI$9)*$S$85:$S$101) -> 16450 | AJ14: =SUMPRODUCT(($D$85:$D$101=$AE$6)*($E$85:$E$101=AJ$9)*$S$85:$S$101) -> 8620 | AK14: =SUMPRODUCT(($D$85:$D$101=$AE$6)*($E$85:$E$101=AK$9)*$S$85:$S$101) -> 3796 | AL14: =SUMPRODUCT(($D$85:$D$101=$AL$6)*($E$85:$E$101=AL$9)*$S$85:$S$101) -> 12600 | AM14: =SUMPRODUCT(($D$85:$D$101=$AL$6)*($E$85:$E$101=AM$9)*$S$85:$S$101) -> 1920 | AN14: =SUMPRODUCT(($D$85:$D$101=$AL$6)*($E$85:$E$101=AN$9)*$S$85:$S$101) -> 200 | AO14: =SUMPRODUCT(($D$85:$D$101=$AL$6)*($E$85:$E$101=AO$9)*$S$85:$S$101) -> 200 | AP14: =SUMPRODUCT(($D$85:$D$101=$AL$6)*($E$85:$E$101=AP$9)*$S$85:$S$101) -> 2000 | AQ14: =SUMPRODUCT(($D$85:$D$101=$AQ$6)*($E$85:$E$101=AQ$9)*$S$85:$S$101) -> 28837 | AR14: =SUMPRODUCT(($D$85:$D$101=$AQ$6)*($E$85:$E$101=AR$9)*$S$85:$S$101) -> 4030 | AS14: =SUMPRODUCT(($D$85:$D$101=$AQ$6)*($E$85:$E$101=AS$9)*$S$85:$S$101) -> 36782 | AT14: =SUMPRODUCT(($D$85:$D$101=$AQ$6)*($E$85:$E$101=AT$9)*$S$85:$S$101) -> 6753 | AU14: =SUMPRODUCT(($D$85:$D$101=$AQ$6)*($E$85:$E$101=AU$9)*$S$85:$S$101) -> 31830 | AV14: =SUM(AE14:AU14) -> 200341
A15: 支出% | B15: =VALUE(RIGHT(B9,2))/12 -> 0.083333333 | D15: 生活 | E15: 醫療費用 | F15: =180+200 -> 380 | H15: =200+500 -> 700 | S15: =SUM(F15:R15) -> 1080 | V15: =$C$104 -> 202306 | W15: =T104 -> 77913 | X15: =T111 -> 9335 | Y15: =T116 -> 97964 | Z15: =W15+X15+Y15 -> 185212 | AA15: =W15/'2022'!W15-1 -> -0.24926288 | AB15: =X15/'2022'!X15-1 -> -0.43352145 | AC15: =Y15/'2022'!Y15-1 -> 0.29482672 | AD15: =V15 -> 202306 | AE15: =SUMPRODUCT(($D$104:$D$120=$AE$6)*($E$104:$E$120=AE$9)*$S$104:$S$120) -> 33677 | AF15: =SUMPRODUCT(($D$104:$D$120=$AE$6)*($E$104:$E$120=AF$9)*$S$104:$S$120) -> 935 | AG15: =SUMPRODUCT(($D$104:$D$120=$AE$6)*($E$104:$E$120=AG$9)*$S$104:$S$120) -> 6598 | AH15: =SUMPRODUCT(($D$104:$D$120=$AE$6)*($E$104:$E$120=AH$9)*$S$104:$S$120) -> 180 | AI15: =SUMPRODUCT(($D$104:$D$120=$AE$6)*($E$104:$E$120=AI$9)*$S$104:$S$120) -> 24000 | AJ15: =SUMPRODUCT(($D$104:$D$120=$AE$6)*($E$104:$E$120=AJ$9)*$S$104:$S$120) -> 6867 | AK15: =SUMPRODUCT(($D$104:$D$120=$AE$6)*($E$104:$E$120=AK$9)*$S$104:$S$120) -> 5656 | AL15: =SUMPRODUCT(($D$104:$D$120=$AL$6)*($E$104:$E$120=AL$9)*$S$104:$S$120) -> 6100 | AM15: =SUMPRODUCT(($D$104:$D$120=$AL$6)*($E$104:$E$120=AM$9)*$S$104:$S$120) -> 0 | AN15: =SUMPRODUCT(($D$104:$D$120=$AL$6)*($E$104:$E$120=AN$9)*$S$104:$S$120) -> 0 | AO15: =SUMPRODUCT(($D$104:$D$120=$AL$6)*($E$104:$E$120=AO$9)*$S$104:$S$120) -> 0 | AP15: =SUMPRODUCT(($D$104:$D$120=$AL$6)*($E$104:$E$120=AP$9)*$S$104:$S$120) -> 3235 | AQ15: =SUMPRODUCT(($D$104:$D$120=$AQ$6)*($E$104:$E$120=AQ$9)*$S$104:$S$120) -> 26357 | AR15: =SUMPRODUCT(($D$104:$D$120=$AQ$6)*($E$104:$E$120=AR$9)*$S$104:$S$120) -> 0 | AS15: =SUMPRODUCT(($D$104:$D$120=$AQ$6)*($E$104:$E$120=AS$9)*$S$104:$S$120) -> 57778 | AT15: =SUMPRODUCT(($D$104:$D$120=$AQ$6)*($E$104:$E$120=AT$9)*$S$104:$S$120) -> 0 | AU15: =SUMPRODUCT(($D$104:$D$120=$AQ$6)*($E$104:$E$120=AU$9)*$S$104:$S$120) -> 13829 | AV15: =SUM(AE15:AU15) -> 185212
A16: 剩餘/超支 $$ | B16: =B10*VALUE(RIGHT(B9,2))-B13 -> -25340 | D16: 想要&奢侈品 | E16: N | M16: 199 | O16: 290 | S16: =SUM(F16:R16) -> 489 | T16: =SUM(S16:S20) -> 47777 | V16: =$C$123 -> 202307 | W16: =T123 -> 80948 | X16: =T130 -> 13438 | Y16: =T135 -> 134425 | Z16: =W16+X16+Y16 -> 228811 | AA16: =W16/'2022'!W16-1 -> -0.12490541 | AB16: =X16/'2022'!X16-1 -> -0.51969405 | AC16: =Y16/'2022'!Y16-1 -> 2.6077563 | AD16: =V16 -> 202307 | AE16: =SUMPRODUCT(($D$123:$D$139=$AE$6)*($E$123:$E$139=AE$9)*$S$123:$S$139) -> 29831 | AF16: =SUMPRODUCT(($D$123:$D$139=$AE$6)*($E$123:$E$139=AF$9)*$S$123:$S$139) -> 600 | AG16: =SUMPRODUCT(($D$123:$D$139=$AE$6)*($E$123:$E$139=AG$9)*$S$123:$S$139) -> 10336 | AH16: =SUMPRODUCT(($D$123:$D$139=$AE$6)*($E$123:$E$139=AH$9)*$S$123:$S$139) -> 900 | AI16: =SUMPRODUCT(($D$123:$D$139=$AE$6)*($E$123:$E$139=AI$9)*$S$123:$S$139) -> 11500 | AJ16: =SUMPRODUCT(($D$123:$D$139=$AE$6)*($E$123:$E$139=AJ$9)*$S$123:$S$139) -> 20042 | AK16: =SUMPRODUCT(($D$123:$D$139=$AE$6)*($E$123:$E$139=AK$9)*$S$123:$S$139) -> 7739 | AL16: =SUMPRODUCT(($D$123:$D$139=$AL$6)*($E$123:$E$139=AL$9)*$S$123:$S$139) -> 3458 | AM16: =SUMPRODUCT(($D$123:$D$139=$AL$6)*($E$123:$E$139=AM$9)*$S$123:$S$139) -> 2680 | AN16: =SUMPRODUCT(($D$123:$D$139=$AL$6)*($E$123:$E$139=AN$9)*$S$123:$S$139) -> 380 | AO16: =SUMPRODUCT(($D$123:$D$139=$AL$6)*($E$123:$E$139=AO$9)*$S$123:$S$139) -> 1570 | AP16: =SUMPRODUCT(($D$123:$D$139=$AL$6)*($E$123:$E$139=AP$9)*$S$123:$S$139) -> 5350 | AQ16: =SUMPRODUCT(($D$123:$D$139=$AQ$6)*($E$123:$E$139=AQ$9)*$S$123:$S$139) -> 53035 | AR16: =SUMPRODUCT(($D$123:$D$139=$AQ$6)*($E$123:$E$139=AR$9)*$S$123:$S$139) -> 4414 | AS16: =SUMPRODUCT(($D$123:$D$139=$AQ$6)*($E$123:$E$139=AS$9)*$S$123:$S$139) -> 63957 | AT16: =SUMPRODUCT(($D$123:$D$139=$AQ$6)*($E$123:$E$139=AT$9)*$S$123:$S$139) -> 0 | AU16: =SUMPRODUCT(($D$123:$D$139=$AQ$6)*($E$123:$E$139=AU$9)*$S$123:$S$139) -> 13019 | AV16: =SUM(AE16:AU16) -> 228811
A17: 剩餘/超支 $$(本月) | B17: =$J$2-(S26-F23) -> -25340 | D17: 想要&奢侈品 | E17: A | F17: =34800+2000 -> 36800 | O17: =9500+99*2 -> 9698 | S17: =SUM(F17:R17) -> 46498 | V17: =$C$142 -> 202308 | W17: =T142 -> 115480 | X17: =T149 -> 16620 | Y17: =T154 -> 118038 | Z17: =W17+X17+Y17 -> 250138 | AA17: =W17/'2022'!W17-1 -> 0.073054693 | AB17: =X17/'2022'!X17-1 -> 2.0345079 | AC17: =Y17/'2022'!Y17-1 -> 2.0426086 | AD17: =V17 -> 202308 | AE17: =SUMPRODUCT(($D$142:$D$158=$AE$6)*($E$142:$E$158=AE$9)*$S$142:$S$158) -> 22419 | AF17: =SUMPRODUCT(($D$142:$D$158=$AE$6)*($E$142:$E$158=AF$9)*$S$142:$S$158) -> 437 | AG17: =SUMPRODUCT(($D$142:$D$158=$AE$6)*($E$142:$E$158=AG$9)*$S$142:$S$158) -> 13445 | AH17: =SUMPRODUCT(($D$142:$D$158=$AE$6)*($E$142:$E$158=AH$9)*$S$142:$S$158) -> 200 | AI17: =SUMPRODUCT(($D$142:$D$158=$AE$6)*($E$142:$E$158=AI$9)*$S$142:$S$158) -> 48495 | AJ17: =SUMPRODUCT(($D$142:$D$158=$AE$6)*($E$142:$E$158=AJ$9)*$S$142:$S$158) -> 24868 | AK17: =SUMPRODUCT(($D$142:$D$158=$AE$6)*($E$142:$E$158=AK$9)*$S$142:$S$158) -> 5616 | AL17: =SUMPRODUCT(($D$142:$D$158=$AL$6)*($E$142:$E$158=AL$9)*$S$142:$S$158) -> 4700 | AM17: =SUMPRODUCT(($D$142:$D$158=$AL$6)*($E$142:$E$158=AM$9)*$S$142:$S$158) -> 3980 | AN17: =SUMPRODUCT(($D$142:$D$158=$AL$6)*($E$142:$E$158=AN$9)*$S$142:$S$158) -> 2670 | AO17: =SUMPRODUCT(($D$142:$D$158=$AL$6)*($E$142:$E$158=AO$9)*$S$142:$S$158) -> 60 | AP17: =SUMPRODUCT(($D$142:$D$158=$AL$6)*($E$142:$E$158=AP$9)*$S$142:$S$158) -> 5210 | AQ17: =SUMPRODUCT(($D$142:$D$158=$AQ$6)*($E$142:$E$158=AQ$9)*$S$142:$S$158) -> 53241 | AR17: =SUMPRODUCT(($D$142:$D$158=$AQ$6)*($E$142:$E$158=AR$9)*$S$142:$S$158) -> 780 | AS17: =SUMPRODUCT(($D$142:$D$158=$AQ$6)*($E$142:$E$158=AS$9)*$S$142:$S$158) -> 50588 | AT17: =SUMPRODUCT(($D$142:$D$158=$AQ$6)*($E$142:$E$158=AT$9)*$S$142:$S$158) -> 0 | AU17: =SUMPRODUCT(($D$142:$D$158=$AQ$6)*($E$142:$E$158=AU$9)*$S$142:$S$158) -> 13429 | AV17: =SUM(AE17:AU17) -> 250138
D18: 想要&奢侈品 | E18: L | F18: 150 | S18: =SUM(F18:R18) -> 150 | V18: =$C$161 -> 202309 | W18: =T161 -> 131306 | X18: =T168 -> 13494 | Y18: =T173 -> 45011 | Z18: =W18+X18+Y18 -> 189811 | AA18: =W18/'2022'!W18-1 -> 0.19905395 | AB18: =X18/'2022'!X18-1 -> 1.225998 | AC18: =Y18/'2022'!Y18-1 -> -0.47022822 | AD18: =V18 -> 202309 | AE18: =SUMPRODUCT(($D$161:$D$177=$AE$6)*($E$161:$E$177=AE$9)*$S$161:$S$177) -> 24451 | AF18: =SUMPRODUCT(($D$161:$D$177=$AE$6)*($E$161:$E$177=AF$9)*$S$161:$S$177) -> 1000 | AG18: =SUMPRODUCT(($D$161:$D$177=$AE$6)*($E$161:$E$177=AG$9)*$S$161:$S$177) -> 10397 | AH18: =SUMPRODUCT(($D$161:$D$177=$AE$6)*($E$161:$E$177=AH$9)*$S$161:$S$177) -> 450 | AI18: =SUMPRODUCT(($D$161:$D$177=$AE$6)*($E$161:$E$177=AI$9)*$S$161:$S$177) -> 15175 | AJ18: =SUMPRODUCT(($D$161:$D$177=$AE$6)*($E$161:$E$177=AJ$9)*$S$161:$S$177) -> 64650 | AK18: =SUMPRODUCT(($D$161:$D$177=$AE$6)*($E$161:$E$177=AK$9)*$S$161:$S$177) -> 15183 | AL18: =SUMPRODUCT(($D$161:$D$177=$AL$6)*($E$161:$E$177=AL$9)*$S$161:$S$177) -> 2104 | AM18: =SUMPRODUCT(($D$161:$D$177=$AL$6)*($E$161:$E$177=AM$9)*$S$161:$S$177) -> 170 | AN18: =SUMPRODUCT(($D$161:$D$177=$AL$6)*($E$161:$E$177=AN$9)*$S$161:$S$177) -> 610 | AO18: =SUMPRODUCT(($D$161:$D$177=$AL$6)*($E$161:$E$177=AO$9)*$S$161:$S$177) -> 610 | AP18: =SUMPRODUCT(($D$161:$D$177=$AL$6)*($E$161:$E$177=AP$9)*$S$161:$S$177) -> 10000 | AQ18: =SUMPRODUCT(($D$161:$D$177=$AQ$6)*($E$161:$E$177=AQ$9)*$S$161:$S$177) -> 0 | AR18: =SUMPRODUCT(($D$161:$D$177=$AQ$6)*($E$161:$E$177=AR$9)*$S$161:$S$177) -> 0 | AS18: =SUMPRODUCT(($D$161:$D$177=$AQ$6)*($E$161:$E$177=AS$9)*$S$161:$S$177) -> 31162 | AT18: =SUMPRODUCT(($D$161:$D$177=$AQ$6)*($E$161:$E$177=AT$9)*$S$161:$S$177) -> 2020 | AU18: =SUMPRODUCT(($D$161:$D$177=$AQ$6)*($E$161:$E$177=AU$9)*$S$161:$S$177) -> 11829 | AV18: =SUM(AE18:AU18) -> 189811
D19: 想要&奢侈品 | E19: D | F19: =150+200 -> 350 | S19: =SUM(F19:R19) -> 350 | V19: =$C$180 -> 202310 | W19: =T180 -> 74439 | X19: =T187 -> 11500 | Y19: =T192 -> 167513.51 | Z19: =W19+X19+Y19 -> 253452.51 | AA19: =W19/'2022'!W19-1 -> 0.20291846 | AB19: =X19/'2022'!X19-1 -> -0.69214295 | AC19: =Y19/'2022'!Y19-1 -> 2.9702671 | AD19: =V19 -> 202310 | AE19: =SUMPRODUCT(($D$180:$D$196=$AE$6)*($E$180:$E$196=AE$9)*$S$180:$S$196) -> 22339 | AF19: =SUMPRODUCT(($D$180:$D$196=$AE$6)*($E$180:$E$196=AF$9)*$S$180:$S$196) -> 0 | AG19: =SUMPRODUCT(($D$180:$D$196=$AE$6)*($E$180:$E$196=AG$9)*$S$180:$S$196) -> 18446 | AH19: =SUMPRODUCT(($D$180:$D$196=$AE$6)*($E$180:$E$196=AH$9)*$S$180:$S$196) -> 250 | AI19: =SUMPRODUCT(($D$180:$D$196=$AE$6)*($E$180:$E$196=AI$9)*$S$180:$S$196) -> 20565 | AJ19: =SUMPRODUCT(($D$180:$D$196=$AE$6)*($E$180:$E$196=AJ$9)*$S$180:$S$196) -> 0 | AK19: =SUMPRODUCT(($D$180:$D$196=$AE$6)*($E$180:$E$196=AK$9)*$S$180:$S$196) -> 12839 | AL19: =SUMPRODUCT(($D$180:$D$196=$AL$6)*($E$180:$E$196=AL$9)*$S$180:$S$196) -> 600 | AM19: =SUMPRODUCT(($D$180:$D$196=$AL$6)*($E$180:$E$196=AM$9)*$S$180:$S$196) -> 2350 | AN19: =SUMPRODUCT(($D$180:$D$196=$AL$6)*($E$180:$E$196=AN$9)*$S$180:$S$196) -> 1795 | AO19: =SUMPRODUCT(($D$180:$D$196=$AL$6)*($E$180:$E$196=AO$9)*$S$180:$S$196) -> 1355 | AP19: =SUMPRODUCT(($D$180:$D$196=$AL$6)*($E$180:$E$196=AP$9)*$S$180:$S$196) -> 5400 | AQ19: =SUMPRODUCT(($D$180:$D$196=$AQ$6)*($E$180:$E$196=AQ$9)*$S$180:$S$196) -> 160974.51 | AR19: =SUMPRODUCT(($D$180:$D$196=$AQ$6)*($E$180:$E$196=AR$9)*$S$180:$S$196) -> 3150 | AS19: =SUMPRODUCT(($D$180:$D$196=$AQ$6)*($E$180:$E$196=AS$9)*$S$180:$S$196) -> 3389 | AT19: =SUMPRODUCT(($D$180:$D$196=$AQ$6)*($E$180:$E$196=AT$9)*$S$180:$S$196) -> 0 | AU19: =SUMPRODUCT(($D$180:$D$196=$AQ$6)*($E$180:$E$196=AU$9)*$S$180:$S$196) -> 0 | AV19: =SUM(AE19:AU19) -> 253452.51
D20: 想要&奢侈品 | E20: 其它 | F20: 290 | S20: =SUM(F20:R20) -> 290 | V20: =$C$199 -> 202311 | W20: =T199 -> 66255 | X20: =T206 -> 8180 | Y20: =T211 -> 49015 | Z20: =W20+X20+Y20 -> 123450 | AA20: =W20/'2022'!W20-1 -> 0.12617283 | AB20: =X20/'2022'!X20-1 -> -0.39888301 | AC20: =Y20/'2022'!Y20-1 -> -0.213457 | AD20: =V20 -> 202311 | AE20: =SUMPRODUCT(($D$199:$D$215=$AE$6)*($E$199:$E$215=AE$9)*$S$199:$S$215) -> 25918 | AF20: =SUMPRODUCT(($D$199:$D$215=$AE$6)*($E$199:$E$215=AF$9)*$S$199:$S$215) -> 0 | AG20: =SUMPRODUCT(($D$199:$D$215=$AE$6)*($E$199:$E$215=AG$9)*$S$199:$S$215) -> 12350 | AH20: =SUMPRODUCT(($D$199:$D$215=$AE$6)*($E$199:$E$215=AH$9)*$S$199:$S$215) -> 0 | AI20: =SUMPRODUCT(($D$199:$D$215=$AE$6)*($E$199:$E$215=AI$9)*$S$199:$S$215) -> 15806 | AJ20: =SUMPRODUCT(($D$199:$D$215=$AE$6)*($E$199:$E$215=AJ$9)*$S$199:$S$215) -> 7180 | AK20: =SUMPRODUCT(($D$199:$D$215=$AE$6)*($E$199:$E$215=AK$9)*$S$199:$S$215) -> 5001 | AL20: =SUMPRODUCT(($D$199:$D$215=$AL$6)*($E$199:$E$215=AL$9)*$S$199:$S$215) -> 0 | AM20: =SUMPRODUCT(($D$199:$D$215=$AL$6)*($E$199:$E$215=AM$9)*$S$199:$S$215) -> 800 | AN20: =SUMPRODUCT(($D$199:$D$215=$AL$6)*($E$199:$E$215=AN$9)*$S$199:$S$215) -> 1110 | AO20: =SUMPRODUCT(($D$199:$D$215=$AL$6)*($E$199:$E$215=AO$9)*$S$199:$S$215) -> 510 | AP20: =SUMPRODUCT(($D$199:$D$215=$AL$6)*($E$199:$E$215=AP$9)*$S$199:$S$215) -> 5760 | AQ20: =SUMPRODUCT(($D$199:$D$215=$AQ$6)*($E$199:$E$215=AQ$9)*$S$199:$S$215) -> 26326 | AR20: =SUMPRODUCT(($D$199:$D$215=$AQ$6)*($E$199:$E$215=AR$9)*$S$199:$S$215) -> 3572 | AS20: =SUMPRODUCT(($D$199:$D$215=$AQ$6)*($E$199:$E$215=AS$9)*$S$199:$S$215) -> 5338 | AT20: =SUMPRODUCT(($D$199:$D$215=$AQ$6)*($E$199:$E$215=AT$9)*$S$199:$S$215) -> 11779 | AU20: =SUMPRODUCT(($D$199:$D$215=$AQ$6)*($E$199:$E$215=AU$9)*$S$199:$S$215) -> 2000 | AV20: =SUM(AE20:AU20) -> 123450
D21: 一次性支出 | E21: 旅遊 | F21: =180+200+80+95+215+135+374+30+24320+190+50+30+100+200+45+105+600+500+120+40 -> 27609 | H21: =5665+260+1364+135+250 -> 7674 | I21: =125+1249+400+400 -> 2174 | J21: 2286 | O21: 238 | S21: =SUM(F21:R21) -> 39981 | T21: =SUM(S21:S25) -> 86141 | V21: =$C$218 -> 202312 | W21: =T218 -> 66375 | X21: =T225 -> 10826 | Y21: =T230 -> 16020 | Z21: =W21+X21+Y21 -> 93221 | AA21: =W21/'2022'!W21-1 -> -0.29284481 | AB21: =X21/'2022'!X21-1 -> -0.64298905 | AC21: =Y21/'2022'!Y21-1 -> -0.72498798 | AD21: =V21 -> 202312 | AE21: =SUMPRODUCT(($D$218:$D$234=$AE$6)*($E$218:$E$234=AE$9)*$S$218:$S$234) -> 23031 | AF21: =SUMPRODUCT(($D$218:$D$234=$AE$6)*($E$218:$E$234=AF$9)*$S$218:$S$234) -> 0 | AG21: =SUMPRODUCT(($D$218:$D$234=$AE$6)*($E$218:$E$234=AG$9)*$S$218:$S$234) -> 11302 | AH21: =SUMPRODUCT(($D$218:$D$234=$AE$6)*($E$218:$E$234=AH$9)*$S$218:$S$234) -> 450 | AI21: =SUMPRODUCT(($D$218:$D$234=$AE$6)*($E$218:$E$234=AI$9)*$S$218:$S$234) -> 20575 | AJ21: =SUMPRODUCT(($D$218:$D$234=$AE$6)*($E$218:$E$234=AJ$9)*$S$218:$S$234) -> 9017 | AK21: =SUMPRODUCT(($D$218:$D$234=$AE$6)*($E$218:$E$234=AK$9)*$S$218:$S$234) -> 2000 | AL21: =SUMPRODUCT(($D$218:$D$234=$AL$6)*($E$218:$E$234=AL$9)*$S$218:$S$234) -> 2997 | AM21: =SUMPRODUCT(($D$218:$D$234=$AL$6)*($E$218:$E$234=AM$9)*$S$218:$S$234) -> 1290 | AN21: =SUMPRODUCT(($D$218:$D$234=$AL$6)*($E$218:$E$234=AN$9)*$S$218:$S$234) -> 60 | AO21: =SUMPRODUCT(($D$218:$D$234=$AL$6)*($E$218:$E$234=AO$9)*$S$218:$S$234) -> 759 | AP21: =SUMPRODUCT(($D$218:$D$234=$AL$6)*($E$218:$E$234=AP$9)*$S$218:$S$234) -> 5720 | AQ21: =SUMPRODUCT(($D$218:$D$234=$AQ$6)*($E$218:$E$234=AQ$9)*$S$218:$S$234) -> 0 | AR21: =SUMPRODUCT(($D$218:$D$234=$AQ$6)*($E$218:$E$234=AR$9)*$S$218:$S$234) -> 1661 | AS21: =SUMPRODUCT(($D$218:$D$234=$AQ$6)*($E$218:$E$234=AS$9)*$S$218:$S$234) -> 1747 | AT21: =SUMPRODUCT(($D$218:$D$234=$AQ$6)*($E$218:$E$234=AT$9)*$S$218:$S$234) -> 12612 | AU21: =SUMPRODUCT(($D$218:$D$234=$AQ$6)*($E$218:$E$234=AU$9)*$S$218:$S$234) -> 0 | AV21: =SUM(AE21:AU21) -> 93221
D22: 一次性支出 | E22: 家庭聚會 | O22: 1800 | S22: =SUM(F22:R22) -> 1800
D23: 一次性支出 | E23: 稅費 | F23: =27778 -> 27778 | S23: =SUM(F23:R23) -> 27778
D24: 一次性支出 | E24: 保險 | Q24: 6753 | S24: =SUM(F24:R24) -> 6753
D25: 一次性支出 | E25: 其它 | H25: =11829-5000-7000 -> -171 | Q25: =12000-2000 -> 10000 | S25: =SUM(F25:R25) -> 9829
D26: Total | E26: Total | F26: =SUM(F9:F25) -> 135126 | G26: =SUM(G9:G25) -> 0 | H26: =SUM(H9:H25) -> 18223 | I26: =SUM(I9:I25) -> 8765 | J26: =SUM(J9:J25) -> 4176 | K26: =SUM(K9:K25) -> 0 | L26: =SUM(L9:L25) -> 0 | M26: =SUM(M9:M25) -> 436 | ... S26: =SUM(S9:S25) -> 213118
A28: 月份 | B28: 202302 | C28: 202302 | D28: 生活 | E28: 食 | F28: =49+50+250+250+268+1089+130+70+918+150+309+195+69+150+80+800+305+465+28 -> 5625 | H28: =185+80+65+110+55+20+30+118+2112+50+110+43+71+1176+520+100+27+100+270+417+58+20+70+156+0+110+100 -> 6173 | M28: =135+213+500+730+314 -> 1892 | O28: =80+65+478+165+115+90 -> 993 | Q28: =2000+2000+2000+2000 -> 8000 | S28: =SUM(F28:R28) -> 22683 | T28: =SUM(S28:S34) -> 89755
A29: 預計支出/月 | B29: =$J$2 -> 160000 | D29: 生活 | E29: 衣 | S29: =SUM(F29:R29) -> 0
A30: Total(到本月) | B30: =SUMPRODUCT((($V$10:$V$21)<=VALUE(B28))*($Z$10:$Z$21)) -> 406751 | D30: 生活 | E30: 住 | F30: 3028 | H30: 174 | M30: 1069 | Q30: =10500-7000+596 -> 4096 | S30: =SUM(F30:R30) -> 8367
